Workbook

Sheet Country-regions
A1: Countries, per region, worked on by [Insert Program/Accelerator name]
A2: CGIAR regions and countries.xlsx | B2: <-- Spreadsheet showing the CGIAR regions and the countries that fall into these regions
A3: Program and Accelerator's Countries (2024).xlsx | B3: <-- Spreadsheet showing the countries that each Program/Accelerator is working on (as per what was submitted in 2024 for the original methodology).
A4: LAC | B4: CWANA | C4: WCA | D4: ESA | E4: SA | F4: SEA
A5: Guatemala | C5: Benin | D5: Ethiopia | E5: Bangladesh | F5: the Philippines
A6: Honduras | C6: Ghana | D6: Kenya | E6: India | F6: Vietnam
C7: Nigeria | D7: Malawi | E7: Sri Lanka
D8: Tanzania
D9: Uganda

Sheet HLOs
A2: VH | B2: 5
A3: H | B3: 4
A4: MH | B4: 3
A5: M | B5: 2
A6: L | B6: 1
C7: # | D7: HLO + concise description
A8: HLO count: | B8: =COUNTA(D8:D29) -> 22 | C8: 1 | D8: AoW1-Suite of solutions focused on consumers that promote consumption of sustainable heathy diets co-developed, tested, and scaled with technical support and country engagement
A9: Sets of 5: | B9: =_xlfn.FLOOR.MATH(B8/5) -> 4 | C9: 2 | D9: AoW1-Suite of solutions focused on vendors that promote employment opportunities and the sale of sustainable nutritious foods co-developed, tested, and scaled with technical support and country engagement
A10: Remainder: | B10: =MOD(B8,5) -> 2 | C10: 3 | D10: AoW1-Policy options and engagement that support effective management of national action plans and other policy processes, for food systems transformation in support of sustainable healthy diets
A11: Max score: | B11: =(B9*SUM($B$2:$B$6))+SUM(B2:INDEX(B:B, $B$10+1)) -> 69 | C11: 4 | D11: AoW2-Suite of Solutions to lower transaction costs
C12: 5 | D12: AoW2-Suite of Solutions to catalyze business growth
C13: 6 | D13: AoW2-Trade and Limiting UPC Consumption
C14: 7 | D14: AoW3-Suite of tested end-to-end solutions for health and agriculture extension agents, fruit and vegetable vendors/retailers, processors, traders and producers that promote healthy food choice behaviors of consumers, healthy food environments, food quality and safety, reduce food loss, and increase profits co-developed, tested, and scaled.
C15: 8 | D15: AoW3-Suite of end-to-end solutions for health and agriculture extension agents, aquatic food vendors/retailers processors, and traders that promote healthy food choice behaviors of consumers, healthy food environments, food quality and safety, reduce food loss, and increase profits co-developed, tested, and scaled.
C16: 9 | D16: AoW3-Suite of end-to-end solutions for health and agriculture extension agents, terrestrial animal-source vendors/retailers processors, and traders that promote healthy food choice behaviors of consumers, healthy food environments, food quality and safety, reduce food loss, and increase profits co-developed, tested, and scaled.
C17: 10 | D17: AoW3-Suite of integrated end-to-end solutions for health and agriculture extension agents, perishable nutrient-rich food vendors/retailers, processors, traders and producers that promote healthy food choice behaviors of consumers, healthy food environments, food quality and safety, reduce food loss,and increase profits co-developed, tested, and scaled.
C18: 11 | D18: AoW3-Policy options that address constraints to sustainable healthy diets
C19: 12 | D19: AoW4-Suite of solutions for producers and processors that address constraints to sustainable healthy diets co-developed, tested, and scaled with technical support and country engagement.
C20: 13 | D20: AoW4-Policy options and engagement that address constraints to sustainable healthy diets.
C21: 14 | D21: AoW4-Framework for embedding nutrition into breeding pipelines and processes.
C22: 15 | D22: AoW4-Suite of solutions for traders and vendors that address constraints to sustainable healthy diets co-developed, tested, and scaled with technical support and country engagement.
C23: 16 | D23: AoW4-Suite of solutions to support consumers awareness, preference, affordability, and utilization of biofortified and health-enhancing crops in their diets.
... C29: 22 | D29: AoW6-Task force that guides the CGIAR Portfolio along pathways that lead to credible impacts on nutrition, health, and food security

Sheet Indicators
A1: BASE Indicator database - (from 2024).xlsx | C1: <-- source of Baseline data
A2: Projected Benefits Data (Nov 2024) - With Analysis.xlsx | C2: <-- source of Projected data (with graphs)
A3: Impact Area | B3: Projected to 2040 (without CGIAR intervention) or baseline data? | C3: Indicator | D3: r_lac | E3: r_cwana | F3: r_wca | G3: r_esa | H3: r_sa | I3: r_sea
A5: Nutrition | B5: Baseline data | C5: Prevalence of stunting (height for age <-2 standard deviation from the median of the World Health Organization (WHO) Child Growth Standards) % children under 5 years of age | D5: 11.679145 | E5: 17.238147 | F5: 31.597628 | G5: 30.494793 | H5: 34.286344 | I5: 11.083749
A6: Nutrition | B6: Baseline data | C6: Prevalence of wasting (weight for height >+2 or <-2 standard deviation from the median of the WHO Child Growth Standards) % children under 5 years of age | D6: 2.2309085 | E6: 5.8629686 | F6: 6.7930741 | G6: 5.4676809 | H6: 16.318465 | I6: 3.6836782
A7: Nutrition | B7: Baseline data | C7: % of population unable to afford a healthy diet | D7: 22.261332 | E7: 37.375529 | F7: 84.372957 | G7: 82.105349 | H7: 73.246664 | I7: 24.396071
A8: Nutrition | B8: Baseline data | C8: Women not meeting minimum dietary diversity (MDD-W)(%) | D8: =100-D9 -> 22.613111 | E8: =100-E9 -> 26.568838 | F8: =100-F9 -> 52.174582 | G8: =100-G9 -> 52.544997 | H8: =100-H9 -> 55.210105 | I8: =100-I9 -> 15.387626
A9: Nutrition | B9: Baseline data | C9: Women meeting minimum dietary diversity (MDD-W)(%) | D9: 77.386889 | E9: 73.431162 | F9: 47.825418 | G9: 47.455003 | H9: 44.789895 | I9: 84.612374
A10: Nutrition | B10: Baseline data | C10: GloMIP Nutrition Priority Index based on indicators in rows 5-8 | D10: 0.080637 | E10: 0.1247 | F10: 0.2064 | G10: 0.1967 | H10: 0.2402 | I10: 0.085998
A11: Gender | B11: Baseline data | C11: Proportion of youth (aged 15-24 years) not in education, employment or training (NEET) (%) | D11: 20.353948 | E11: 28.808683 | F11: 22.22403 | G11: 22.032946 | H11: 25.579269 | I11: 13.900333
A12: Gender | B12: Baseline data | C12: Gender Development Index (GDI) | D12: 0.98711807 | E12: 0.86109472 | F12: 0.88128823 | G12: 0.92987576 | H12: 0.85713094 | I12: 0.96249076 | J12: GDI measures gender inequalities in achievement in three basic dimensions of human development: health, measured by female and male life expectancy at birth; education, measured by female and male expected years of schooling for children and female and male mean years of schooling for adults ages 25 years and older; and command over economic resources, measured by female and male estimated earned income.
A13: Gender | B13: Baseline data | C13: Gender Inequality Index (GII) | D13: 0.3786 | E13: 0.4202 | F13: 0.6154 | G13: 0.51 | H13: 0.4542 | I13: 0.2426 | J13: GII is a composite metric of gender inequality using three dimensions: reproductive health, empowerment and the labour market. A low GII value indicates low inequality between women and men, and vice-versa.
A14: Poverty | B14: Baseline data | C14: The ratio of the people employed in agriculture in rural areas over all people employed in rural areas" | D14: 46.830763 | E14: 34.609244 | F14: 64.335138 | G14: 71.949092 | H14: 56.611142 | I14: 44.992877
A15: Climate | B15: Baseline data | C15: Vulnerability index of the geography (exposure, sensitivity and adaptive capacity in six life-supporting sectors: food, water, health, ecosystem services, human habitat, and infrastructure). | D15: 0.38522854 | E15: 0.41856096 | F15: 0.52689312 | G15: 0.51707456 | H15: 0.50168331 | I15: 0.40802057
A16: Climate | B16: Baseline data | C16: Emissions intensity - CO2eq emissions from croplands (kg/ha) (Carlson et al., 2017) | D16: 386 | E16: 444 | F16: 312 | G16: 531 | H16: 2090 | I16: 3326
A17: Climate | B17: Baseline data | C17: CRI - Climate Risk Index - the index of the level of exposure and vulnerability to extreme events such as storms, floods and heatwaves based on historic data | D17: 46.593083 | E17: 71.63158 | F17: 73.530172 | G17: 45.434032 | H17: 18.194338 | I17: 40.16028
A18: Environment | B18: Baseline data | C18: Consumptive blue and green water used in food production (m3/ha) | D18: 5008.9819 | E18: 3795.1862 | F18: 4064.7898 | G18: 4368.5844 | H18: 5065.8423 | I18: 6113.5583
A19: Environment | B19: Baseline data | C19: Soil erosion rate (/Ha) | D19: 4480.2558 | E19: 2629.3874 | F19: 5858.9939 | G19: 7924.0507 | H19: 10121.16 | I19: 7076.2489
A20: Environment | B20: Baseline data | C20: Forest area lost (%) - the percentage of forested area (%) lost between 2010 and 2020 | D20: 4.0133292 | E20: 3.0328342 | F20: 8.736605 | G20: 6.4758874 | H20: 0.80036497 | I20: 1.9236632
A21: Environment | B21: Baseline data | C21: GBI - Global Biodiversity Index - Total number of plant, reptile, mammal, bird, fish and amphibian species | D21: 362.31193 | E21: 80.081948 | F21: 116.18798 | G21: 156.28684 | H21: 264.30093 | I21: 324.04395
A22: Environment | B22: Baseline data | C22: Sustainable agriculture score - Index quantifying progress toward productive and sustainable agriculture (current status score) | D22: 3.7142926 | E22: 3.0915505 | F22: 3.2533234 | G22: 2.8150793 | H22: 2.5514288 | I22: 3.9867322
A24: Impact Area | B24: Projected to 2040 (without CGIAR intervention) | C24: Indicator | D24: r_lac | X24: r_cwana | AR24: r_wca | BL24: r_esa | CF24: r_sa | CZ24: r_sea
D25: 2021 | E25: 2022 | F25: 2023 | G25: 2024 | H25: 2025 | I25: 2026 | J25: 2027 | K25: 2028 | L25: 2029 | M25: 2030 | N25: 2031 | O25: 2032 | P25: 2033 | Q25: 2034 | R25: 2035 | S25: 2036 | T25: 2037 | U25: 2038 | V25: 2039 | W25: 2040 | X25: 2021 | Y25: 2022 | Z25: 2023 | AA25: 2024 | AB25: 2025 | AC25: 2026 | AD25: 2027 | AE25: 2028 | AF25: 2029 | AG25: 2030 | AH25: 2031 | AI25: 2032 | AJ25: 2033 | AK25: 2034 | AL25: 2035 | AM25: 2036 | AN25: 2037 | AO25: 2038 | AP25: 2039 | AQ25: 2040 | AR25: 2021 | AS25: 2022 | AT25: 2023 | AU25: 2024 | AV25: 2025 | AW25: 2026 | AX25: 2027 | AY25: 2028 | AZ25: 2029 | BA25: 2030 | BB25: 2031 | BC25: 2032 | BD25: 2033 | BE25: 2034 | BF25: 2035 | BG25: 2036 | BH25: 2037 | BI25: 2038 | BJ25: 2039 | BK25: 2040 | BL25: 2021 | BM25: 2022 | BN25: 2023 | BO25: 2024 | BP25: 2025 | BQ25: 2026 | BR25: 2027 | BS25: 2028 | BT25: 2029 | BU25: 2030 | BV25: 2031 | BW25: 2032 | BX25: 2033 | BY25: 2034 | BZ25: 2035 | CA25: 2036 | CB25: 2037 | CC25: 2038 | CD25: 2039 | CE25: 2040 | CF25: 2021 | CG25: 2022 | CH25: 2023 | CI25: 2024 | CJ25: 2025 | CK25: 2026 | CL25: 2027 | CM25: 2028 | CN25: 2029 | CO25: 2030 | CP25: 2031 | CQ25: 2032 | CR25: 2033 | CS25: 2034 | CT25: 2035 | CU25: 2036 | CV25: 2037 | CW25: 2038 | CX25: 2039 | CY25: 2040 | CZ25: 2021 | DA25: 2022 | DB25: 2023 | DC25: 2024 | DD25: 2025 | DE25: 2026 | DF25: 2027 | DG25: 2028 | DH25: 2029 | DI25: 2030 | DJ25: 2031 | DK25: 2032 | DL25: 2033 | DM25: 2034 | DN25: 2035 | DO25: 2036 | DP25: 2037 | DQ25: 2038 | DR25: 2039 | DS25: 2040
A26: Nutrition | B26: Projected to 2040 | C26: Prevalence of Undernourishment - Share of total population living below the minimum calorie daily threshold | D26: 7.1892578 | E26: 6.68889 | F26: 6.2115266 | G26: 5.7570393 | H26: 5.3252329 | I26: 4.9158466 | J26: 4.5285569 | K26: 4.1629803 | L26: 3.8186764 | M26: 3.4951517 | N26: 3.1918631 | O26: 2.908223 | P26: 2.6436027 | Q26: 2.3973382 | R26: 2.1687341 | S26: 1.9570691 | T26: 1.7616009 | U26: 1.5815713 | V26: 1.4162109 | W26: 1.2647443 | X26: 9.1504665 | Y26: 8.9091662 | Z26: 8.6634743 | AA26: 8.4138444 | AB26: 8.160744 | AC26: 7.9046538 | AD26: 7.6460667 | AE26: 7.3854859 | AF26: 7.123424 | AG26: 6.8604013 | AH26: 6.5969443 | AI26: 6.3335834 | AJ26: 6.0708516 | AK26: 5.809282 | AL26: 5.5494058 | AM26: 5.2917502 | AN26: 5.0368357 | AO26: 4.7851739 | AP26: 4.537265 | AQ26: 4.2935953 | AR26: 18.91209 | AS26: 18.415278 | AT26: 17.911492 | AU26: 17.401678 | AV26: 16.886799 | AW26: 16.367828 | AX26: 15.845748 | AY26: 15.321548 | AZ26: 14.796218 | BA26: 14.270749 | BB26: 13.746128 | BC26: 13.223332 | BD26: 12.703327 | BE26: 12.187064 | BF26: 11.675475 | BG26: 11.169467 | BH26: 10.669921 | BI26: 10.177686 | BJ26: 9.6935781 | BK26: 9.2183741 | BL26: 22.510157 | BM26: 21.490211 | BN26: 20.474437 | BO26: 19.465188 | BP26: 18.464847 | BQ26: 17.475809 | BR26: 16.500465 | BS26: 15.541184 | BT26: 14.600291 | BU26: 13.680052 | BV26: 12.782652 | BW26: 11.910171 | BX26: 11.064571 | BY26: 10.247669 | BZ26: 9.4611245 | CA26: 8.7064163 | CB26: 7.9848318 | CC26: 7.2974499 | CD26: 6.645131 | CE26: 6.0285075 | CF26: 15.036352 | CG26: 13.50078 | CH26: 12.058387 | CI26: 10.711231 | CJ26: 9.460449 | CK26: 8.306251 | CL26: 7.2479364 | CM26: 6.2839238 | CN26: 5.4118015 | CO26: 4.6283937 | CP26: 3.9298411 | CQ26: 3.3116949 | CR26: 2.76902 | CS26: 2.2965049 | CT26: 1.8885759 | CU26: 1.53951 | CV26: 1.2435457 | CW26: 0.99498599 | CX26: 0.78829295 | CY26: 0.6181697 | CZ26: 2.9870488 | DA26: 2.5739841 | DB26: 2.2066181 | DC26: 1.8817105 | DD26: 1.5959854 | DE26: 1.3461739 | DF26: 1.1290543 | DG26: 0.94148797 | DH26: 0.78045059 | DI26: 0.64305899 | DJ26: 0.52659245 | DK26: 0.42850921 | DL26: 0.34645781 | DM26: 0.27828373 | DN26: 0.2220316 | DO26: 0.1759435 | DP26: 0.13845375 | DQ26: 0.10818092 | DR26: 0.083917403 | DS26: 0.06461742
A27: Gender | B27: WE CURRENTLY DON’T HAVE APPROPRIATE INDICATORS PROJECTED FOR THE GENDER IMPACT AREA - PLEASE USE BASELINE DATA ONLY
A28: Poverty | B28: Projected to 2040 | C28: Poverty Headcount Rate ($2.15) - Share of total population living below the poverty line | D28: 4.98557 | E28: 5.0242558 | F28: 5.0621172 | G28: 5.0991222 | H28: 5.1352386 | I28: 5.1704341 | J28: 5.2046757 | K28: 5.2379303 | L28: 5.2701643 | M28: 5.3013441 | N28: 5.3314354 | O28: 5.3604039 | P28: 5.3882149 | Q28: 5.4148334 | R28: 5.4402242 | S28: 5.4643519 | T28: 5.4871807 | U28: 5.5086747 | V28: 5.5287977 | W28: 5.5475134 | X28: 4.59918 | Y28: 4.4042124 | Z28: 4.2131091 | AA28: 4.02598 | AB28: 3.84293 | AC28: 3.6640582 | AD28: 3.4894579 | AE28: 3.319216 | AF28: 3.1534129 | AG28: 2.9921218 | AH28: 2.8354089 | AI28: 2.6833326 | AJ28: 2.5359435 | AK28: 2.3932841 | AL28: 2.2553884 | AM28: 2.1222821 | AN28: 1.9939817 | AO28: 1.8704952 | AP28: 1.7518213 | AQ28: 1.6379496 | AR28: 36.30807 | AS28: 36.185862 | AT28: 36.061701 | AU28: 35.935577 | AV28: 35.807479 | AW28: 35.677395 | AX28: 35.545315 | AY28: 35.411226 | AZ28: 35.275116 | BA28: 35.136975 | BB28: 34.996788 | BC28: 34.854543 | BD28: 34.710229 | BE28: 34.56383 | BF28: 34.415335 | BG28: 34.26473 | BH28: 34.112002 | BI28: 33.957135 | BJ28: 33.800117 | BK28: 33.640934 | BL28: 38.89568 | BM28: 38.85434 | BN28: 38.811608 | BO28: 38.767445 | BP28: 38.721807 | BQ28: 38.674652 | BR28: 38.625933 | BS28: 38.575602 | BT28: 38.523611 | BU28: 38.469907 | BV28: 38.414438 | BW28: 38.357148 | BX28: 38.297978 | BY28: 38.236869 | BZ28: 38.173758 | CA28: 38.10858 | CB28: 38.041268 | CC28: 37.97175 | CD28: 37.899953 | CE28: 37.825801 | CF28: 11.48274 | CG28: 10.469358 | CH28: 9.4825203 | CI28: 8.5274757 | CJ28: 7.6094386 | CK28: 6.7334754 | CL28: 5.904376 | CM28: 5.126516 | CN28: 4.4037126 | CO28: 3.7390816 | CP28: 3.134903 | CQ28: 2.5925037 | CR28: 2.1121683 | CS28: 1.6930861 | CT28: 1.3333448 | CU28: 1.0299761 | CV28: 0.77905634 | CW28: 0.57586239 | CX28: 0.41507324 | CY28: 0.29100712 | CZ28: 1.23059 | DA28: 0.88984793 | DB28: 0.6221891 | DC28: 0.41911725 | DD28: 0.27092336 | DE28: 0.16738356 | DF28: 0.098482932 | DG28: 0.055066945 | DH28: 0.029330068 | DI28: 0.015081471 | DJ28: 0.0077742847 | DK28: 0.0043346014 | DL28: 0.0028635352 | DM28: 0.0022984445 | DN28: 0.0021059525 | DO28: 0.0020486343 | DP28: 0.0020339519 | DQ28: 0.002030774 | DR28: 0.0020302043 | DS28: 0.0020301216
A29: Poverty | B29: Projected to 2040 | C29: Poverty Headcount Rate ($3.65) - Share of total population living below the poverty line | D29: 12.326178 | E29: 12.381889 | F29: 12.436252 | G29: 12.489232 | H29: 12.540798 | I29: 12.590913 | J29: 12.639544 | K29: 12.686654 | L29: 12.732209 | M29: 12.776171 | N29: 12.818504 | O29: 12.85917 | P29: 12.898132 | Q29: 12.935351 | R29: 12.970787 | S29: 13.004401 | T29: 13.036154 | U29: 13.066003 | V29: 13.093907 | W29: 13.119826 | X29: 14.288423 | Y29: 13.982703 | Z29: 13.67684 | AA29: 13.370967 | AB29: 13.065221 | AC29: 12.759739 | AD29: 12.454666 | AE29: 12.150146 | AF29: 11.846328 | AG29: 11.543362 | AH29: 11.241404 | AI29: 10.940608 | AJ29: 10.641135 | AK29: 10.343146 | AL29: 10.046804 | AM29: 9.7522739 | AN29: 9.4597232 | AO29: 9.1693202 | AP29: 8.8812344 | AQ29: 8.5956364 | AR29: 64.127509 | AS29: 64.124548 | AT29: 64.121536 | AU29: 64.118473 | AV29: 64.115359 | AW29: 64.112192 | AX29: 64.108972 | AY29: 64.105699 | AZ29: 64.102372 | BA29: 64.098991 | BB29: 64.095554 | BC29: 64.092063 | BD29: 64.088515 | BE29: 64.08491 | BF29: 64.081248 | BG29: 64.077527 | BH29: 64.073748 | BI29: 64.06991 | BJ29: 64.066011 | BK29: 64.062051 | BL29: 65.516569 | BM29: 65.515305 | BN29: 65.513998 | BO29: 65.512647 | BP29: 65.511251 | BQ29: 65.509807 | BR29: 65.508315 | BS29: 65.506774 | BT29: 65.50518 | BU29: 65.503534 | BV29: 65.501833 | BW29: 65.500075 | BX29: 65.498258 | BY29: 65.496382 | BZ29: 65.494442 | CA29: 65.492439 | CB29: 65.490368 | CC29: 65.488229 | CD29: 65.486018 | CE29: 65.483733 | CF29: 43.13417 | CG29: 42.785936 | CH29: 42.423103 | CI29: 42.045096 | CJ29: 41.651323 | CK29: 41.241181 | CL29: 40.814053 | CM29: 40.369309 | CN29: 39.906311 | CO29: 39.424414 | CP29: 38.922966 | CQ29: 38.401314 | CR29: 37.858808 | CS29: 37.294802 | CT29: 36.708661 | CU29: 36.099766 | CV29: 35.467522 | CW29: 34.811364 | CX29: 34.130765 | CY29: 33.425246 | CZ29: 6.6233529 | DA29: 5.5934126 | DB29: 4.6450586 | DC29: 3.7861739 | DD29: 3.0226307 | DE29: 2.3578335 | DF29: 1.7923687 | DG29: 1.323821 | DH29: 0.94680861 | DI29: 0.65326964 | DJ29: 0.43300161 | DK29: 0.2744137 | DL29: 0.16540941 | DM29: 0.094283044 | DN29: 0.050501138 | DO29: 0.025256507 | DP29: 0.011729008 | DQ29: 0.0050518673 | DR29: 0.0020459537 | DS29: 0.00082542745
A30: Poverty | B30: Projected to 2040 | C30: Poverty Headcount Rate ($6.85) - Share of total population living below the poverty line | D30: 31.99797 | E30: 32.039063 | F30: 32.079058 | G30: 32.117939 | H30: 32.155689 | I30: 32.192292 | J30: 32.227729 | K30: 32.261984 | L30: 32.295038 | M30: 32.326872 | N30: 32.357466 | O30: 32.386801 | P30: 32.414856 | Q30: 32.441611 | R30: 32.467043 | S30: 32.491131 | T30: 32.513851 | U30: 32.535181 | V30: 32.555096 | W30: 32.573571 | X30: 39.779017 | Y30: 39.643681 | Z30: 39.506381 | AA30: 39.367094 | AB30: 39.225797 | AC30: 39.082466 | AD30: 38.937077 | AE30: 38.789605 | AF30: 38.640025 | AG30: 38.488313 | AH30: 38.334443 | AI30: 38.178388 | AJ30: 38.020124 | AK30: 37.859624 | AL30: 37.69686 | AM30: 37.531806 | AN30: 37.364435 | AO30: 37.194718 | AP30: 37.022628 | AQ30: 36.848136 | AR30: 88.509867 | AS30: 88.506906 | AT30: 88.503894 | AU30: 88.500831 | AV30: 88.497716 | AW30: 88.494549 | AX30: 88.49133 | AY30: 88.488056 | AZ30: 88.48473 | BA30: 88.481348 | BB30: 88.477912 | BC30: 88.47442 | BD30: 88.470872 | BE30: 88.467267 | BF30: 88.463605 | BG30: 88.459885 | BH30: 88.456106 | BI30: 88.452267 | BJ30: 88.448368 | BK30: 88.444408 | BL30: 87.43947 | BM30: 87.438206 | BN30: 87.4369 | BO30: 87.435549 | BP30: 87.434152 | BQ30: 87.432709 | BR30: 87.431217 | BS30: 87.429675 | BT30: 87.428082 | BU30: 87.426435 | BV30: 87.424734 | BW30: 87.422976 | BX30: 87.42116 | BY30: 87.419283 | BZ30: 87.417344 | CA30: 87.41534 | CB30: 87.413269 | CC30: 87.41113 | CD30: 87.408919 | CE30: 87.406634 | CF30: 80.974435 | CG30: 80.959243 | CH30: 80.943388 | CI30: 80.92684 | CJ30: 80.909568 | CK30: 80.891539 | CL30: 80.872719 | CM30: 80.853071 | CN30: 80.832558 | CO30: 80.811141 | CP30: 80.788779 | CQ30: 80.765429 | CR30: 80.741045 | CS30: 80.71558 | CT30: 80.688986 | CU30: 80.66121 | CV30: 80.632198 | CW30: 80.601895 | CX30: 80.57024 | CY30: 80.537172 | CZ30: 29.55282 | DA30: 28.453081 | DB30: 27.310321 | DC30: 26.125513 | DD30: 24.900204 | DE30: 23.636605 | DF30: 22.337679 | DG30: 21.007236 | DH30: 19.650019 | DI30: 18.271781 | DJ30: 16.879345 | DK30: 15.480643 | DL30: 14.084712 | DM30: 12.701646 | DN30: 11.342485 | DO30: 10.019034 | DP30: 8.7435908 | DQ30: 7.528593 | DR30: 6.3861649 | DS30: 5.327589
A31: Poverty | B31: Projected to 2040 | C31: Agrifood System Jobs (incl. subsistence farming and informal sector) - millions of workers | D31: 79.453806 | E31: 81.086566 | F31: 82.7612 | G31: 84.478933 | H31: 86.241033 | I31: 88.048807 | J31: 89.903606 | K31: 91.806824 | L31: 93.759905 | M31: 95.764336 | N31: 97.821657 | O31: 99.933458 | P31: 102.10138 | Q31: 104.32713 | R31: 106.61247 | S31: 108.95919 | T31: 111.3692 | U31: 113.84443 | V31: 116.3869 | W31: 118.99868 | X31: 50.377779 | Y31: 51.475884 | Z31: 52.606947 | AA31: 53.772164 | AB31: 54.972781 | AC31: 56.210098 | AD31: 57.485472 | AE31: 58.800317 | AF31: 60.156109 | AG31: 61.554391 | AH31: 62.996771 | AI31: 64.48493 | AJ31: 66.020625 | AK31: 67.605691 | AL31: 69.242045 | AM31: 70.931693 | AN31: 72.676732 | AO31: 74.479356 | AP31: 76.341859 | AQ31: 78.266643 | AR31: 118.18601 | AS31: 122.23843 | AT31: 126.45317 | AU31: 130.8372 | AV31: 135.39785 | AW31: 140.14274 | AX31: 145.07984 | AY31: 150.21751 | AZ31: 155.56444 | BA31: 161.12976 | BB31: 166.92299 | BC31: 172.9541 | BD31: 179.23348 | BE31: 185.77203 | BF31: 192.58113 | BG31: 199.67268 | BH31: 207.05915 | BI31: 214.75354 | BJ31: 222.76947 | BK31: 231.1212 | BL31: 152.33566 | BM31: 158.07421 | BN31: 164.07237 | BO31: 170.34342 | BP31: 176.90137 | BQ31: 183.76104 | BR31: 190.93808 | BS31: 198.44902 | BT31: 206.31135 | BU31: 214.54355 | BV31: 223.16518 | BW31: 232.19692 | BX31: 241.66066 | BY31: 251.57954 | BZ31: 261.9781 | CA31: 272.88229 | CB31: 284.3196 | CC31: 296.31915 | CD31: 308.91182 | CE31: 322.1303 | CF31: 335.11902 | CG31: 345.66882 | CH31: 356.63814 | CI31: 368.04754 | CJ31: 379.91877 | CK31: 392.27487 | CL31: 405.14024 | CM31: 418.54076 | CN31: 432.50383 | CO31: 447.05854 | CP31: 462.23575 | CQ31: 478.06821 | CR31: 494.5907 | CS31: 511.84016 | CT31: 529.85585 | CU31: 548.6795 | CV31: 568.3555 | CW31: 588.93105 | CX31: 610.45641 | CY31: 632.98506 | CZ31: 430.51747 | DA31: 439.33041 | DB31: 448.38064 | DC31: 457.67536 | DD31: 467.22202 | DE31: 477.02828 | DF31: 487.10209 | DG31: 497.45165 | DH31: 508.08544 | DI31: 519.0122 | DJ31: 530.24097 | DK31: 541.7811 | DL31: 553.64225 | DM31: 565.8344 | DN31: 578.36786 | DO31: 591.25328 | DP31: 604.5017 | DQ31: 618.12449 | DR31: 632.13342 | DS31: 646.54069
A32: Poverty | B32: Projected to 2040 | C32: Agrifood System GDP Per Worker - US$ per worker | D32: 9757.9382 | E32: 9757.9382 | F32: 9757.9382 | G32: 9757.9382 | H32: 9757.9382 | I32: 9757.9382 | J32: 9757.9382 | K32: 9757.9382 | L32: 9757.9382 | M32: 9757.9382 | N32: 9757.9382 | O32: 9757.9382 | P32: 9757.9382 | Q32: 9757.9382 | R32: 9757.9382 | S32: 9757.9382 | T32: 9757.9382 | U32: 9757.9382 | V32: 9757.9382 | W32: 9757.9382 | X32: 11320.812 | Y32: 11320.812 | Z32: 11320.812 | AA32: 11320.812 | AB32: 11320.812 | AC32: 11320.812 | AD32: 11320.812 | AE32: 11320.812 | AF32: 11320.812 | AG32: 11320.812 | AH32: 11320.812 | AI32: 11320.812 | AJ32: 11320.812 | AK32: 11320.812 | AL32: 11320.812 | AM32: 11320.812 | AN32: 11320.812 | AO32: 11320.812 | AP32: 11320.812 | AQ32: 11320.812 | AR32: 2860.2434 | AS32: 2860.2434 | AT32: 2860.2434 | AU32: 2860.2434 | AV32: 2860.2434 | AW32: 2860.2434 | AX32: 2860.2434 | AY32: 2860.2434 | AZ32: 2860.2434 | BA32: 2860.2434 | BB32: 2860.2434 | BC32: 2860.2434 | BD32: 2860.2434 | BE32: 2860.2434 | BF32: 2860.2434 | BG32: 2860.2434 | BH32: 2860.2434 | BI32: 2860.2434 | BJ32: 2860.2434 | BK32: 2860.2434 | BL32: 1686.5692 | BM32: 1686.5692 | BN32: 1686.5692 | BO32: 1686.5692 | BP32: 1686.5692 | BQ32: 1686.5692 | BR32: 1686.5692 | BS32: 1686.5692 | BT32: 1686.5692 | BU32: 1686.5692 | BV32: 1686.5692 | BW32: 1686.5692 | BX32: 1686.5692 | BY32: 1686.5692 | BZ32: 1686.5692 | CA32: 1686.5692 | CB32: 1686.5692 | CC32: 1686.5692 | CD32: 1686.5692 | CE32: 1686.5692 | CF32: 2772.7337 | CG32: 2772.7337 | CH32: 2772.7337 | CI32: 2772.7337 | CJ32: 2772.7337 | CK32: 2772.7337 | CL32: 2772.7337 | CM32: 2772.7337 | CN32: 2772.7337 | CO32: 2772.7337 | CP32: 2772.7337 | CQ32: 2772.7337 | CR32: 2772.7337 | CS32: 2772.7337 | CT32: 2772.7337 | CU32: 2772.7337 | CV32: 2772.7337 | CW32: 2772.7337 | CX32: 2772.7337 | CY32: 2772.7337 | CZ32: 8556.862 | DA32: 8556.862 | DB32: 8556.862 | DC32: 8556.862 | DD32: 8556.862 | DE32: 8556.862 | DF32: 8556.862 | DG32: 8556.862 | DH32: 8556.862 | DI32: 8556.862 | DJ32: 8556.862 | DK32: 8556.862 | DL32: 8556.862 | DM32: 8556.862 | DN32: 8556.862 | DO32: 8556.862 | DP32: 8556.862 | DQ32: 8556.862 | DR32: 8556.862 | DS32: 8556.862
A33: Climate | B33: Projected to 2040 | C33: Agrifood System Greenhouse Gas (GHG) Emissions | D33: 1290.6349 | E33: 1299.4607 | F33: 1308.4565 | G33: 1317.627 | H33: 1326.977 | I33: 1336.5113 | J33: 1346.2348 | K33: 1356.1529 | L33: 1366.2709 | M33: 1376.5942 | N33: 1387.1287 | O33: 1397.8802 | P33: 1408.8548 | Q33: 1420.0587 | R33: 1431.4986 | S33: 1443.181 | T33: 1455.113 | U33: 1467.3017 | V33: 1479.7545 | W33: 1492.4791 | X33: 521.24598 | Y33: 532.37733 | Z33: 543.82156 | AA33: 555.58869 | AB33: 567.68908 | AC33: 580.13348 | AD33: 592.93304 | AE33: 606.09934 | AF33: 619.64439 | AG33: 633.58065 | AH33: 647.92106 | AI33: 662.67905 | AJ33: 677.86859 | AK33: 693.50417 | AL33: 709.60086 | AM33: 726.17432 | AN33: 743.24082 | AO33: 760.81729 | AP33: 778.92133 | AQ33: 797.57126 | AR33: 420.59141 | AS33: 431.825 | AT33: 443.40263 | AU33: 455.3357 | AV33: 467.63605 | AW33: 480.31594 | AX33: 493.38808 | AY33: 506.86563 | AZ33: 520.76222 | BA33: 535.09201 | BB33: 549.86963 | BC33: 565.11028 | BD33: 580.82972 | BE33: 597.04426 | BF33: 613.77085 | BG33: 631.02704 | BH33: 648.83104 | BI33: 667.20175 | BJ33: 686.15877 | BK33: 705.72241 | BL33: 552.78648 | BM33: 575.08538 | BN33: 598.466 | BO33: 622.98755 | BP33: 648.71274 | BQ33: 675.70795 | BR33: 704.0435 | BS33: 733.79384 | BT33: 765.03783 | BU33: 797.85902 | BV33: 832.34591 | BW33: 868.59228 | BX33: 906.69748 | BY33: 946.76683 | BZ33: 988.91191 | CA33: 1033.251 | CB33: 1079.9095 | CC33: 1129.0204 | CD33: 1180.7245 | CE33: 1235.1714 | CF33: 1337.1419 | CG33: 1368.6614 | CH33: 1401.2786 | CI33: 1435.0419 | CJ33: 1470.0024 | CK33: 1506.2136 | CL33: 1543.732 | CM33: 1582.6166 | CN33: 1622.9297 | CO33: 1664.7367 | CP33: 1708.1063 | CQ33: 1753.1111 | CR33: 1799.8271 | CS33: 1848.3343 | CT33: 1898.7173 | CU33: 1951.0646 | CV33: 2005.4699 | CW33: 2062.0314 | CX33: 2120.8529 | CY33: 2182.0435 | CZ33: 2408.5001 | DA33: 2440.4414 | DB33: 2473.2397 | DC33: 2506.9196 | DD33: 2541.5063 | DE33: 2577.0259 | DF33: 2613.5052 | DG33: 2650.9722 | DH33: 2689.4553 | DI33: 2728.9842 | DJ33: 2769.5894 | DK33: 2811.3024 | DL33: 2854.1556 | DM33: 2898.1827 | DN33: 2943.4182 | DO33: 2989.8979 | DP33: 3037.6588 | DQ33: 3086.7389 | DR33: 3137.1777 | DS33: 3189.0156
A36: Prevalence of Undernourishment
A54: Undernourished Population
A71: Poverty Headcount Rate ($2.15)
A87: Poverty Headcount Rate ($3.65)
A104: Poverty Headcount Rate ($6.85)
A121: Agrifood System Jobs (incl. subsistence farming and informal sector)
A139: Agricultural Jobs (incl. subsistence farming and informal sector)
A156: Agricultural Greenhouse Gas (GHG) Emissions

Sheet 1.Food_security
C1: FS Indicators
A2: VH | B2: 5 | D2: LAC | E2: CWANA | F2: WCA | G2: ESA | H2: SA | I2: SEA | J2: AoW1 | K2: =AVERAGE(D11:I13) -> 3.4 | L2: We proportionally reduced the scores to meet the maxima.
A3: H | B3: 4 | C3: Total score by column | D3: =SUM(D11:D59) -> 61 | E3: =SUM(E11:E59) -> 29 | F3: =SUM(F11:F59) -> 69 | G3: =SUM(G11:G59) -> 69 | H3: =SUM(H11:H59) -> 69 | I3: =SUM(I11:I59) -> 63 | J3: AoW2 | K3: =AVERAGE(D14:I16) -> 3
A4: MH | B4: 3 | C4: VH count by column | D4: =COUNTIF(D$11:D$59, 5) -> 2 | E4: =COUNTIF(E$11:E$59, 5) -> 0 | F4: =COUNTIF(F$11:F$59, 5) -> 1 | G4: =COUNTIF(G$11:G$59, 5) -> 2 | H4: =COUNTIF(H$11:H$59, 5) -> 1 | I4: =COUNTIF(I$11:I$59, 5) -> 1 | J4: AoW3 | K4: =AVERAGE(D17:I21) -> 3.36
A5: M | B5: 2 | C5: H count by column | D5: =COUNTIF(D$11:D$59, 4) -> 1 | E5: =COUNTIF(E$11:E$59, 4) -> 0 | F5: =COUNTIF(F$11:F$59, 4) -> 6 | G5: =COUNTIF(G$11:G$59, 4) -> 6 | H5: =COUNTIF(H$11:H$59, 4) -> 8 | I5: =COUNTIF(I$11:I$59, 4) -> 7 | J5: AoW4 | K5: =AVERAGE(D22:I26) -> 2.8333333
A6: L | B6: 1 | C6: MH count by column | D6: =COUNTIF(D$11:D$59, 3) -> 10 | E6: =COUNTIF(E$11:E$59, 3) -> 9 | F6: =COUNTIF(F$11:F$59, 3) -> 10 | G6: =COUNTIF(G$11:G$59, 3) -> 7 | H6: =COUNTIF(H$11:H$59, 3) -> 6 | I6: =COUNTIF(I$11:I$59, 3) -> 8 | J6: AoW5 | K6: =AVERAGE(D27:I27) -> 3.6
C7: M count by column | D7: =COUNTIF(D$11:D$59, 2) -> 8 | E7: =COUNTIF(E$11:E$59, 2) -> 1 | F7: =COUNTIF(F$11:F$59, 2) -> 5 | G7: =COUNTIF(G$11:G$59, 2) -> 7 | H7: =COUNTIF(H$11:H$59, 2) -> 7 | I7: =COUNTIF(I$11:I$59, 2) -> 3 | J7: AoW6 | K7: =AVERAGE(D28:I32) -> 2.8666667
C8: L count by column | D8: =COUNTIF(D$11:D$59, 1) -> 1 | E8: =COUNTIF(E$11:E$59, 1) -> 0 | F8: =COUNTIF(F$11:F$59, 1) -> 0 | G8: =COUNTIF(G$11:G$59, 1) -> 0 | H8: =COUNTIF(H$11:H$59, 1) -> 0 | I8: =COUNTIF(I$11:I$59, 1) -> 0 | K8: Current state (across the Global South) | L8: Ideal state (across the Global South) | M8: Assumptions (for region-specific scores) | N8: Requirements for success (internal to P/A) | O8: Requirements for success (from other P/As)
C10: HLO | D10: LAC | E10: CWANA | F10: WCA | G10: ESA | H10: SA | I10: SEA
A11: HLO count: | B11: =COUNTA(C11:C59) -> 22 | C11: AoW1-Suite of solutions focused on consumers that promote consumption of sustainable heathy diets co-developed, tested, and scaled with technical support and country engagement | D11: 3 | F11: 4 | G11: 4 | H11: 4 | I11: 3 | K11: 1. Behavior change solutions for consumers in LMICs exist (like national Food-Based Dietary Guidelines), but (a) evidence on their effectiveness is lacking, (b) they are not being used at scale, and (c) they do not address enough components of the food system to make an impact (in other words, they are not transformative solutions). 2. There are very few known solutions in LMICs that address the food environment. 3. Metrics are not all-encompassing. 4. Metrics are not being used by gov'ts for decisionmaking. 5. Uneven willingness to act 6. There may be information on what governments can do, but very little information on how do it. | L11: 1. Behavior change solutions for consumers in LMICs are evidence-based, used at scale and broad enough to contribute to meaningful positive food system transformation. 2. Key evidence-based solutions to shape LMIC food environments in favor of sustainable healthy diets are widely available and effecively used. 3. Coherent, complete and consistent metrics are widely used. 4. These metrics guide governmental decision-making contributing to greater consumption of sustainable healthy diets in LMICs. 5. Political barriers and lock-ins are overcome with governments and other food system stakeholders willing and able to act. 6. Clear policy roadmaps based on solid evidence exist to guide governmental decision-making. | M11: WCA - There are few behavior change solutions currently under implementation across WCA countries. Therefore there is potential for very high change in this region. ESA & SA - Some initial advances such as FBDG exist in some countries but there is limited work at scale, scant evidence and relatively low willingness to act. We feel that this region shows a high potential for impact. LAC & SEA - These regions have done more work on consumer-facing solutions including FBDG as well as innovations around food labeling, taxes on sugar sweetened beverages and policy control of food companies in terms of product formulation and marketing. Despite this, evidence remains spotty on the effectiveness of these approaches. CGIAR has much to learn here with solid partners. We estimate a medium high potential for impact here. | N11: Evidence is relevant (helps meet government actors' goals) and timely for government actors to use. Gov’t actors perceive their institutions have the capacity to implement the solutions. | O11: From CGIAR's production-oriented Programs: We need sustainable nutritious foods to be available, affordable, safe, sustainably produced even in the midst of local and global shocks and resilient in the face of climate change. Scaling for Impact: We'll need their expertise to help us scale our own tested solutions.
A12: Sets of 5: | B12: =_xlfn.FLOOR.MATH(B11/5) -> 4 | C12: AoW1-Suite of solutions focused on vendors that promote employment opportunities and the sale of sustainable nutritious foods co-developed, tested, and scaled with technical support and country engagement | D12: 3 | F12: 3 | G12: 3 | H12: 3 | I12: 4 | K12: 1. There is a lack of data about MSMEs and informal actors in LMICs - what are barriers and constraints to their businesses, what incentives are there to grow their business, and similar questions for barriers/constraints/incentives for selling sustainable nutritious foods. 2. There is a lack of data on the presence of healthy foods being sold by MSMEs and informal actors in LMICs. 3. There are few evidence-based solutions for how to improve conditions for MSMEs and informal actors in LMICs selling food. 4. The increasing presence of ultra-processed foods (UPFs) combined with infrastructure realities (e.g., widely variable access to cold storage and clean water) changes the cost-benefits for MSME and informal actors. 5. Successful and aggressive commercial strategies of multinational food companies increase the availability and affordability of UPFs being offered by MSMEs and informal actors in LMICs. | L12: 1. Deeper understanding of MSMEs and informal sector in LMICs drives effective support for them to provide sustainable nutritious foods. 2. The role of MSMEs and informal actors in providing sustainable nutritious foods is well documented and widely understood in LMICs. 3. A suite of evidence-based solutions exists to support the sale of sustainable nutritous foods by MSMEs and informal actors in LMICs. 4. There is growing recognition of how infrastructure realities and the rise of UPFs influence MSME decision-making, enabling more informed strategies to support healthier food environments. 5. Smart evidence-based gov't regulations are in place that constrain and limit the spread of UPFs and favor more sustainable nutritious foods. | M12: WCA, ESA, SA, SEA - These regions present low levels of data on the role of MSMEs and informal actors in the provision of sustainable nutritious foods. Likewise few evidenced-based solutions have been identified and tested at scale despite the increasing presence of UPFs in their food environments. If BDN can provide evidence to change this, we feel there is potential of high potential impact. LAC - This region has some modest advances compared to other regions in terms of data and understanding of the role of MSMEs and informal actors in the provision of sustainable nutritious foods. Despite that, there are significant political headwinds to act in the food environment which is further exacerbated by the rapid expansion of UPFs driven by agressive commercial strategies. There are modest attempts to counteract this with labeling, taxation and marketing control. If BDN and key regional partners can provide more consistent evidence, we assess a medium high potential for impact. | N12: Evidence is relevant (helps meet their goals) and timely for government actors to use. Gov’t actors perceive their institutions have the capacity to implement the solutions. MSMEs and informal actors perceive the solutions are not harmful to their profit margin and have the capacity to implement the solutions. | O12: We don't think any other Programs are addressing this. Scaling for Impact: We'll need their expertise to help us scale our own tested solutions.
A13: Remainder: | B13: =MOD(B11,5) -> 2 | C13: AoW1-Policy options and engagement that support effective management of national action plans and other policy processes, for food systems transformation in support of sustainable healthy diets | D13: 5 | F13: 2 | G13: 3 | H13: 2 | I13: 5 | K13: 1. Food System Transformation National Action Plans are being developed but at various levels of detail, and hardly being implemented. 2. Lack of policy coherence. There is a lack of clear and consistent food system policies across levels and sectors of government in LMICs. 3. Lack of policy alignment. For example, agricultural policies emphasize maximizing production for economic growth while health policies emphasize health promotion...in some cases, without putting enough emphasis on the role of diets. 4. Policies are on paper, but not in practice. 5. LMIC governments face difficulties to operationalize their aspirations for food systems transformation (issues relate to awareness, capacity, finance, the political economy and so on). 6. The policy landscape in many LMICs is behind the curve. Policies are framed by the issues from 50 years ago (undernourished population, calories) and not the present threats (obesity and overweight and NCDs). | L13: 1. Food system policies in LMICs are clear, consistent, and coherent across sectors and levels of government. 2. Agricultural, health, and other sectoral policies are well-aligned, with a shared emphasis on the role of diets in achieving both economic and health goals. 3. Food system policies are increasingly being translated into effective practice. 4. LMIC governments are successfully operationalizing food systems transformation, supported by growing awareness, stronger capacity, increased financing, and improved political alignment. 5. Policy frameworks in LMICs have been modernized, shifting focus from past challenges to today’s pressing issues such as obesity, overweight, and noncommunicable diseases. | M13: LAC & SEA - These regions show the greatest willingness to engage in building their capacities to achieve policy alignment that lead to food system transformation in practice and at scale. We feel there is very high potential for food system transformation at scale in these regions. ESA - This region has some willingness to engage in policy alignment in support of food system transformation, however this is constrained by political and financial challenges. We feel that that BDN can achieve high potential impact in this region for this HLO. WCA -- This region has shown limited willingess and capacity to engage meaningfully in policy alignment to support food system transformation. We estimate medium high potential for positive change in this HLO. SA -- This region has shown low willingess and capacity to engage meaningfully in policy alignment to support food system transformation. Given this reality, we estimate only a moderate chance to achieve significant change in this HLO. | N13: Decisionmakers have the awareness of political lock-ins and capacity to overcome them to improve sectoral alignment. Decisionmakers have the awareness of trade-offs and how to overcome them. The new governance mechanisms integrate various societal perspectives. | O13: Policy Innovations: we need their quantitative modelling of trade-off analysis Climate Action, Multifunctional Landscapes: we need their help to promote policy coherence across different agendas (climate, biodiversity).
A14: Max score: | B14: =(B12*SUM($B$2:$B$6))+SUM($B$2:INDEX(B:B, $B$13+1)) -> 69 | C14: AoW2-Suite of Solutions to lower transaction costs | D14: 5 | F14: 2 | G14: 4 | H14: 3 | K14: 1. Many products are not quality differentiated by markets, leading to low quality equilibria. This equilibrium holds when quality traits are unobservable (e.g. food safety, but environmental impact, anything that is not visually apparent). 2. Safety of perishable foods often perceived as low, and demand can be reduced for more nutrient dense foods if safe practices cannot be maintained throughout agri-food value chains for perishable products 3. Transaction costs within specific markets for more nutrient dense and perishable products thought to be high, reducing producer prices (and therefore production) and increasing consumer prices (and therefore reducing demand) 4. Post-harvest loss is high among perishable products, which leads to higher consumer prices 5. Technological solutions exist that can help reduce transaction costs, but the return to using those solutions must be high enough for some actor to overcome coordination costs 6. Policy solutions that can help increase availability of more nutrient dense products (quality certification, food safety regulations) often weakly or unevenly enforced | L14: 1. Quality is defined for specific products and markets reward quality with a high enough price difference to reward quality throughout specific value chains; 2. Affordable solutions for food safety concerns are implemented at scale, leading to fewer concerns about food safety and improved health from eating nutrient dense foods 3. More chains adopt technological solutions (e.g. logistics) to reduce transaction costs within value chains for nutrient dense products, increasing affordability 4. Cost-effective solutions to reduce post-harvest losses within chains are found, increasing affordability and accessibility 5. Policies support the implementation of solutions for food safety and other market level concerns | M14: 1. For Latin America, our work is focusing only on the suite of solutions making markets more efficient, so we score it highest. We may work on limiting UPC consumption there if resources come available, so we score it higher than 1. | N14: Internally it is best to understand what products are most required in the diet (AoW1) so we can prioritize them for diets; in this case so that we can target those markets if foodis produced but costly or not available enough for some reason. | O14: We are collaborating with SAAF to develop food safety solutions for animal source foods. To the extent that we are able to demonstrate positive solutions, we will attempt to work with the Scaling for Impact Science Program on scaling them.
C15: AoW2-Suite of Solutions to catalyze business growth | D15: 1 | F15: 3 | G15: 3 | H15: 4 | K15: 1. Many types of actors in markets for nutrient dense foods lack access to formal finance (traders, vendors in particular) 2. Formal financial products are not often tailored to the needs of agri-food businesses selling more nutrient dense foods 3. Demand for financial products may be uncertain in some markets 4. Climate finance funds are not necessarily aware of the nutritional and dietary impacts of their investments in small or medium enterprises 5. Technological solutions exist to reduce the standard transaction costs which drive adverse selection and moral hazard problems, but low uptake as of yet in most markets | L15: 1. Improved access to finance among businesses working in markets for more nutrient dense foods, leading to business growth and improved employment 2. Better designed products with clear explanation to users about how products work (interest rates, payment schedules, etc.) 3. Increased use of technology in loaning value chain actors money 4. Climate finance funds begin to lend to firms working in nutrient dense product markets | M15: 2. In West and Central Africa, coastal countries have more exposure to trade; there is less progress we believe on quality interventions and with our strained capacity we focus primarily on policy and finance for nutrient dense foods in West and Central Africa. Hence we give the lowest score to lowering transaction costs and the highest to trade, an a medium score to catalyzing business growth. | N15: Internally it is best to understand what products are most required in the diet (AoW1) so we can prioritize them for diets. Similarly with better info on UPC consumption we can envision targeting growth work most effectively. | O15: To the extent that we are able to demonstrate positive solutions, we will attempt to work with the Scaling for Impact Science Program on scaling them.
C16: AoW2-Trade and Limiting UPC Consumption | D16: 3 | F16: 4 | G16: 2 | H16: 2 | K16: 1. International Trade contributes to healthier diets in some countries, but not others, and agricultural trade policy can have implications for diets; 2. While subsidies not large enough in most LMICs to change demand for products, some countries with very large markets could repurpose subsidies to improve markets for more nutrient dense foods; 3. Well designed policies can hinder demand for ultra processed foods, but most countries outside of LAC and OECD do not have policies on ultra processed foods | L16: 1. Improved understanding of trade helps governments promote specific types of more nutrient dense foods that fill dietary requirements in countries with substantial food trade; 2. Subsidies are repurposed in India and other large LMICs with subsidies to reduce distortions to markets; 3. LMICs begin to implement policies (labeling, SSB taxes, others) that can help reduce the growth of demand for UPFs | M16: 3. In East and Southern Africa, technology capacity is high, meaning that we focus on use of tech in “solutions” and finance to try to improve affordability and availability of more nutrient dense foods. So we limit work on trade and UPC consumption. 4. In South Asia, finance is relatively important for increasing growth in trade of more nutrient dense products due to availability of solutions but lack of implementation. We then believe the suite of solutions for business growth is most important, followed reducing transaction costs and then by policy.
C17: AoW3-Suite of tested end-to-end solutions for health and agriculture extension agents, fruit and vegetable vendors/retailers, processors, traders and producers that promote healthy food choice behaviors of consumers, healthy food environments, food quality and safety, reduce food loss, and increase profits co-developed, tested, and scaled. | D17: 3 | F17: 3 | G17: 5 | H17: 5 | I17: 3 | K17: 1. In the Global South, fruit and vegetable consumption remains below the recommended 400g per day, which is crucial for preventing chronic diseases. Factors such as food preferences, diet and nutrition knowledge, education, affordability of fruit and vegetables, food safety and quality issues, inadequate supply due to perishability and complex marketing, and poor infrastructure hinder access to and consumption of these foods. 2. Behavior change towards healthier food choices, including increasing the intake of fruits and vegetables, is complex and evidence from interventions to increase fruit and vegetable intake are lacking, despite the exisitence of relevant tools such as national food based dietary guidelines. 3. Food environments incresingly favor promotion of unhealthy foods and there is limited evidence about the impact of changing food environments to support healthier food choices like increasing intake of fruits and vegetables. 4. Fruit and vegetable production has increased by 3.3% annually over the last two decades, but per capita growth is only 0.7%. 5. Supply is not keeping pace with demand and population growth due to a range of complex factors, including poor access to high-quality inputs, high post-harvest loss (up to 50%), significant contamination from pesticide residues due to improper use of chemical products and handling, limited market access, and a lack of improved technologies. 6. Climate change further exacerbates these challenges, leading to rising temperatures, erratic rainfall, and increased pest populations that can potentially reduce yields. 7. There is a growing demand for safe fruit and vegetables, and improved technologies for safe production, post-harvest handling, and storage are available. | L17: 1. Demand for fruit and vegetables increases such that most people meet the recommended intake of 400 g/d 2. Food environments change in ways that support and encourage healthier food choices, including increasing the access to and affordability of fruit and vegetables 3. Fruit and vegetable consumption demand in the Global South is met within planetary boundaries 4. Post-harvest practices improve such that pesitcide contamination and microbial contamination are reduced 5. Stakeholders across fruit and vegetable value chains adopt solutions that promote healthy food choice behaviors of consumers, healthy food environments, food quality and safety, reduce food loss. | M17: 1. WCA and ESA: Solutions are needed to improve fruit and vegetable consumption, production, post-harvest, safety, and market access. Partnerships have been established across the regions. 2. SEA: There are established partnerships in some countries, and the buy-in of stakeholders to deploy solutions that support increasing fruit and vegetable intake. 3. SA: There are established partnerships in some countries and buy-in from stakeholders to deploy solutions that support increaing fruit and vegetable intake. | N17: Evidence from pilot studies and innovations are relevant to the stakeholders they are designed to reach/support Stakeholders across the value chain work together to deploy solutions. Evidence is relevant to country priorities and policymakers have the will to use evidence to inform programs and policies | O17: For translation to urban environments we will work wtih the urban AOW in the Food Fronteirs and Security SP
C18: AoW3-Suite of end-to-end solutions for health and agriculture extension agents, aquatic food vendors/retailers processors, and traders that promote healthy food choice behaviors of consumers, healthy food environments, food quality and safety, reduce food loss, and increase profits co-developed, tested, and scaled. | D18: 3 | F18: 4 | G18: 4 | H18: 3 | I18: 4 | K18: 1. Worldwide in 2032, aquatic animal per capita consumption is likely to increase everywhere except in sub-Saharan Africa where alot of people depend on aquatic foods for animal protein and micronutrients 2. Fish loss and waste estimates in Africa is estimated at around 40% which is far above the global average of 25% having a significant impact of food and nutrition security. 3. In SEA diets are dominated by rice and fish provide the necessary micronutrients. Fish provide 50% of animal protein in Cambodia, Indonesia and Phillipines. Due to the immense pressure fisheries face as a result of high consumption, adressing loss and waste to ensure retention of nutrients within the system is crucial. | L18: 1. Aquatic animal consumption demand in Sub-Saharan Africa is met within planetary boundaries 2. Stakeholders within the aquatic foods value chain adopt climate smart loss and waste technologies | M18: 1. ESA & WCA- this region has had several countries conducting multi dimensional waste and loss studies along fish value chains and indication of willingness to address loss and waste issues. 2. The two regions also have fisheries regional and country specific policies that recognize the role of addressing losss and waste in the fisheries and aquaculture sector indicating a conducive envrionment for introducing waste and loss technologies 3. Several South East Asian countries have recognized the role of fisheries in their national nutrition action plans (LAO, Cambodia, Phillipines, Thailand, Myanmar, Indonesia, Malaysia) | N18: (i) Market actors perceive the food environment solutions as win-win and have the interest and capacity to implement the solutions. (ii) Social cultural factors that hinder consumption of animal source foods, especially for vulnerable populations are amenable to change | O18: (i) Collaboration with the SAAFs SP especially on the production aspects of the aquatic animal source food systems.
C19: AoW3-Suite of end-to-end solutions for health and agriculture extension agents, terrestrial animal-source vendors/retailers processors, and traders that promote healthy food choice behaviors of consumers, healthy food environments, food quality and safety, reduce food loss, and increase profits co-developed, tested, and scaled. | D19: 2 | F19: 3 | G19: 3 | H19: 4 | I19: 3 | K19: 1. High levels of micronutrient deficiencies in Eastern Africa, WCA and SEA - partly due to insufficient consumption of animal source foods. Eastern Africa is known for its large dairy animal populations, but still, most countries in the region consume only a third of the recommended amount of ASFs. 2. Solutions are needed to improve animal source foods intake to recommended levels as part of healthy diets, especially for vulnerable populations – young children, pregnant and lactating women; in addition to healthy food environment related challenges. 3. ESA: Established partnerships in some countries such as Uganda, Tanzania, Ethiopia, Kenya (from SAPLING efforts) | L19: 1. Terrestrial animal source foods demand in Sub-Saharan Africa is met within planetary boundaries 2. Actors within the terestrial animal source foods system adopt solutions that promote healthy food choice behaviors of consumers, healthy food environments, and food safety | M19: ESA: Several countries in this region have made strides in advocating for integration of terrestrial animal source foods as part of healthy diets- particularly targeting vulnerable populations through strong partnerships. Several studies have generated evidence on the impact of interventions that address social cultural constraints to consumption of animals source foods and nutrition education, on diets. Further interventions aimed at healthy food environment will enhance such benefits. | N19: (i) Market actors perceive the food environment solutions as win-win and have the interest and capacity to implement the solutions. (ii) Social cultural factors that hinder consumption of animal source foods, especially for vulnerable populations are amenable to change | O19: (i) Collaboration with the SAAFs SP especially on the production aspects of the terrestrial animal source food systems.
C20: AoW3-Suite of integrated end-to-end solutions for health and agriculture extension agents, perishable nutrient-rich food vendors/retailers, processors, traders and producers that promote healthy food choice behaviors of consumers, healthy food environments, food quality and safety, reduce food loss,and increase profits co-developed, tested, and scaled. | D20: 3 | F20: 3 | G20: 3 | H20: 4 | I20: 3 | K20: 1. In the Global South, fruit and vegetable consumption remains below the recommended 400g per day, which is crucial for preventing chronic diseases. Intake of aquatic foods is also suboptimal as is intake of terrestrial animal source foods (in some cases too high and others too low). Factors such as food preferences, diet and nutrition knowledge, education, affordability of fruit and vegetables, food safety and quality issues, inadequate supply due to perishability and complex marketing, and poor infrastructure hinder access to and consumption of these foods. 2. Behavior change towards healthier food choices, including increasing the intake of fruits and vegetables, is complex and evidence from interventions to increase fruit and vegetable intake are lacking, despite the exisitence of relevant tools such as national food based dietary guidelines. 3. Food environments incresingly favor promotion of unhealthy foods and there is limited evidence about the impact of changing food environments to support healthier food choices like increasing intake of fruits and vegetables. 4. Food loss and waste of fruits and vegetables and aquatic foods is high at around 40%. | L20: 1. Demand for sustainable healthy diets increases 2. Food environments change in ways that support and encourage healthier food choices, including increasing the access to and affordability of fruit and vegetables 3. Perinshable nutrient-rich food consumption demand in the Global South is met within planetary boundaries 4. Post-harvest practices improve such that pesitcide contamination and microbial contamination are reduced 5. Food loss and waste are reduced through improved practices and technoligies | M20: ESA: Well established partnerships exisit. There is buy-in from relevant stakehodlers intreseted in end-to-end solutions to improving diet and nutrition outcomes. Food-based dietary guidelines exist for forcal coutries. Good opportuinities for integration. WCA: Well established partnerships exisit. There is buy-in from relevant stakehodlers intreseted in end-to-end solutions to improving diet and nutrition outcomes. Food-based dietary guidelines exist for forcal coutries. SA: Well established partnerships exisit. There is buy-in from relevant stakehodlers intreseted in end-to-end solutions to improving diet and nutrition outcomes. Food-based dietary guidelines exist for forcal coutries. Good opportuinities for integration. | N20: Actors across sectors are able to work together to deploy more complex integrated solutions, Pilot studies can be conducted to support development of prototypes for integration. | O20: Collaboration with Sustainable Farming, Sustainable Animal and Aquatic Foods to test and pilot integrated solutions
C21: AoW3-Policy options that address constraints to sustainable healthy diets | D21: 4 | F21: 3 | G21: 2 | H21: 3 | I21: 4 | K21: 1. Many countries have multisectoral nutrition action plans, programs and policies, however there is limitied attention paid to how to achieve end-to-end solutions for perishable nutrient-rich foods. 2. While there is some evidence to support taxes on unheathy foods and other products, similar efforts are scant for using subisides, or other incentives to support healthy food choices. 3. In some cases regulations and laws exist to support food safety measures, however these are often not adequately monitored or enforced. 4. Fruits and vegetables are often not prioritized for investments, subsidies or other incentives to support growth of this sector, aside from actions to support development for export in some cases. | L21: 1. Multisectoral nutrition action plans, programs and policies include actions to support end-to-end solutions for increasing intake of perishable nutrient-rich foods. 2. Evidence is generated to understand the inflence of taxes, subsideis or other incentives to support healthy food production and consumption. 3. Regulations and laws related to food safety are updated enforced. 4. Stakeholders across perishable nutrient-rich food value chains adopt solutions that promote healthy food choice behaviors of consumers, healthy food environments, food quality and safety, reduce food loss. | M21: In WCA and ESA policy frameworks remain weak, and stakeholder engagement is often fragmented and inconsistent. Policymakers are open to evidence-based dialogue; institutional champions exist; multisector coordination platforms are functional; and governments are committed to improving diets, public health, and nutrition outcomes. The other regions also have weak policy frameworks and implementation strategies but LAC has some biofortification champions. In SEA policys remain insuffiecient addressing in particular over-nutrition and obesity, while in SA both under- and overnutrition are prevalent with weak policies addressing either. | N21: More syngery with AoW5 and AoW6 to translate evidences into actionable policy and engagement with policy makers
