Workbook

Sheet Country-regions
A1: Countries, per region, worked on by [Insert Program/Accelerator name]
A2: CGIAR regions and countries.xlsx | B2: <-- Spreadsheet showing the CGIAR regions and the countries that fall into these regions
A3: Program and Accelerator's Countries (2024).xlsx | B3: <-- Spreadsheet showing the countries that each Program/Accelerator is working on (as per what was submitted in 2024 for the original methodology).
A4: LAC | B4: CWANA | C4: WCA | D4: ESA | E4: SA | F4: SEA
A5: Colombia | B5: Egypt | C5: Benin | D5: Ethiopia | E5: Bangladesh | F5: Cambodia
A6: Guatemala | B6: Morocco | C6: Côte d’Ivoire | D6: Kenya | E6: India | F6: Indonesia
A7: Honduras | B7: Tunisia | C7: DR Congo | D7: Malawi | E7: Nepal | F7: Myanmar
A8: Mexico | B8: Uzbekistan | C8: Nigeria | D8: Tanzania | E8: Pakistan | F8: Philippines
A9: Peru | C9: Senegal | D9: Uganda | E9: Sri Lanka | F9: Viet Nam
C10: Sudan | D10: Zambia
D11: Zimbabwe
A12: Primary countries
A13: Secondary countries

Sheet HLOs
A2: VH | B2: 5
A3: H | B3: 4
A4: MH | B4: 3
A5: M | B5: 2
A6: L | B6: 1
C7: # | D7: HLO Title | E7: HLO Concise description
A8: HLO count: | B8: =COUNTA(D8:D23) -> 15 | C8: 1 | D8: HLO 1.1.1: Demand signaling | E8: A toolbox of quantitative and qualitative methods, data, and dashboards articulating stakeholders’ priorities, supporting research and scaling activity demand signaling and adaptive anagement of CGIAR’s Portfolio
A9: Sets of 5: | B9: =_xlfn.FLOOR.MATH(B8/5) -> 3 | C9: 2 | D9: HLO 1.1.2: Feedback and adaptive research and scaling prioritization | E9: CGIAR’s Programs, Accelerators, and bilaterals engage with information supporting the adaptive management of Program, Accelerator, and bilateral research and scaling activities
A10: Remainder: | B10: =MOD(B8,5) -> 0 | C10: 3 | D10: HLO 1.1.3: Enhance strategies and coordination | E10: Comprehensive, forward-looking regional and country-level strategies, enhancing Portfolio-wide research prioritization, scaling coordination, and policy alignment
A11: Max score: | B11: =(B9*SUM($B$2:$B$6))+IF(B8=0,0,SUM(B2:INDEX(B:B,$B$10+1))) -> 50 | C11: 4 | D11: HLO 2.2.1: Innovation networks enhance agrifood system solution scaling | E11: Regional scaling hubs supporting stakeholders in impact pathway diagnosis, design, deployment, and refinement
C12: 5 | D12: HLO 2.2.2: Methods evaluating agrifood system solutions for scale | E12: Co-designed scaling pathways for regional and national agrifood systems through improved stakeholder capacity
C13: 6 | D13: HLO 2.2.3: Scale-ready agrifood system solution bundles and packages | E13: Impact pathways evaluated and ranked for their potential to advance innovation bundles and packages to scale in regional- and country-specific agrifood systems
C14: 7 | D14: HLO 2.2.4: Agrifood system solution scaling strategies | E14: Demand-driven and scale-ready agrifood system solution bundles and packages and strategies for scaling, with pathways and strategies identified for refinement, adaptation, and amplification
C15: 8 | D15: HLO 3.3.1: Enabling environment diagnostics | E15: Co-created tools and analyses to assess opportunities and constraints in the enabling environment for innovation bundle scaling in targeted countries and regions and in the three primary pathways
C16: 9 | D16: HLO 3.3.2: Scaling support services for enabling environments and institutions | E16: Innovative institution building and capacity sharing activities; training materials and targeted deployment of demand-driven targeted EE technical assistance to enhance institutional and analytical as well as operational capacities to achieve scale
C17: 10 | D17: HLO 3.3.3: Science-policy partnership interfaces for responsible scaling | E17: Innovative partnerships, policy hubs, economic and environment networks, community-building efforts, and NARES/farmer cooperatives supported to increase research-based public and private investments and policy improvements and address normative barriers
C18: 11 | D18: HLO 4.4.1: CGIAR Expertise and Solutions Embedded in Development Investments and Partnerships | E18: CGIAR engages with financing bodies—including IFIs and the private sector, including banks, impact investors, and CSR funds—through technical assistance and advisory support, to ensure innovations are positioned to support impact at scale
C19: 12 | D19: HLO 4.4.2: Innovation portfolio management and scaling strategy support teams | E19: Scaling capacity toolbox in support of CGIAR Programs and bilateral projects strengthening the design, implementation, and monitoring of evidence-based and responsible scaling strategies
C20: 13 | D20: HLO 5.5.1: Enhancing scaling science for societal impact | E20: An applied scaling science and innovation systems research agenda strengthening South–South learning and capacities to implement more responsible and context-aware scaling strategies
C21: 14 | D21: HLO 5.5.2: Insights for CGIAR scaling success through impact assessments | E21: Evidence-based, context-specific recommendations on optimal scaling outcomes for selected CGIAR scaling efforts and solutions are based on rigorous impact assessments and nalysis of diverse scaling pathways and are supported by co-created scaling metrics, monitoring, and evaluations.
C22: 15 | D22: HLO 5.5.3: Custom analytics for managing innovation portfolios and decision-making | E22: Curated analytics for innovation portfolio management and decision-making, including Scaling Readiness evaluations and customized assessment tools for target countries, both ongoing and as part of the annual adaptive management process, to ensure continuous learning and improvement

Sheet Indicators
A1: BASE Indicator database - (from 2024).xlsx | C1: <-- source of Baseline data
A2: Projected Benefits Data (Nov 2024) - With Analysis.xlsx | C2: <-- source of Projected data (with graphs)
A3: Impact Area | B3: Projected to 2040 (without CGIAR intervention) or baseline data? | C3: Indicator | D3: r_lac | E3: r_cwana | F3: r_wca | G3: r_esa | H3: r_sa | I3: r_sea
K4: Mean | L4: SD | M4: r_lac | N4: r_cwana | O4: r_wca | P4: r_esa | Q4: r_sa | R4: r_sea
A5: Nutrition | B5: Baseline data | C5: Prevalence of stunting (height for age <-2 standard deviation from the median of the World Health Organization (WHO) Child Growth Standards) % children under 5 years of age | D5: 11.679145 | E5: 17.238147 | F5: 31.597628 | G5: 30.494793 | H5: 34.286344 | I5: 11.083749 | K5: 0.2267 | L5: 0.1144 | M5: =D5*5/$H5 -> 1.7031774 | N5: =E5*5/$H5 -> 2.5138502 | O5: =F5*5/$H5 -> 4.6079027 | P5: =G5*5/$H5 -> 4.4470756 | Q5: =H5*5/$H5 -> 5 | R5: =I5*5/$H5 -> 1.6163504 | Y5: r_lac | Z5: r_cwana | AA5: r_wca | AB5: r_esa | AC5: r_sa | AD5: r_sea
A6: Nutrition | B6: Baseline data | C6: Prevalence of wasting (weight for height >+2 or <-2 standard deviation from the median of the WHO Child Growth Standards) % children under 5 years of age | D6: 2.2309085 | E6: 5.8629686 | F6: 6.7930741 | G6: 5.4676809 | H6: 16.318465 | I6: 3.6836782 | K6: 0.0667 | L6: 0.0476 | M6: =D6*5/$H6 -> 0.6835534 | N6: =E6*5/$H6 -> 1.7964216 | O6: =F6*5/$H6 -> 2.0814072 | P6: =G6*5/$H6 -> 1.6753049 | Q6: =H6*5/$H6 -> 5 | R6: =I6*5/$H6 -> 1.128684 | S6: =AVERAGE(M5:M8) -> 2.0697443 | T6: =AVERAGE(N5:N8) -> 2.71611 | U6: =AVERAGE(O5:O8) -> 3.6288645 | V6: =AVERAGE(P5:P8) -> 3.4480649 | W6: =AVERAGE(Q5:Q8) -> 4.2468545 | X6: =AVERAGE(R5:R8) -> 2.2976906 | Y6: =S6*1.1 -> 2.2767187 | Z6: =T6*1.1 -> 2.987721 | AA6: =U6*1.1 -> 3.9917509 | AB6: =V6*1.1 -> 3.7928713 | AC6: =W6*1.1 -> 4.6715399 | AD6: =X6*1.1 -> 2.5274597
A7: Nutrition | B7: Baseline data | C7: % of population unable to afford a healthy diet | D7: 22.261332 | E7: 37.375529 | F7: 84.372957 | G7: 82.105349 | H7: 73.246664 | I7: 24.396071 | K7: 0.5367 | L7: 0.2812 | M7: =D7*5/$F7 -> 1.319222 | N7: =E7*5/$F7 -> 2.2148998 | O7: =F7*5/$F7 -> 5 | P7: =G7*5/$F7 -> 4.86562 | Q7: =H7*5/$F7 -> 4.3406482 | R7: =I7*5/$F7 -> 1.4457281
A8: Nutrition | B8: Baseline data | C8: Women meeting minimum dietary diversity (MDD-W)(%) | D8: 77.386889 | E8: 73.431162 | F8: 47.825418 | G8: 47.455003 | H8: 44.789895 | I8: 84.612374 | J8: MDD-W - higher value indicates more women meeting the minimum (i.e., a lower potential for impact) --- Minimum Dietary Diversity for Women is a population-level food group-based indicator that captures dietary diversity, a core construct of healthy diets. MDD-W is used to estimate the proportion of non-pregnant women aged 15-49 years who consumed at least five out of ten defined food groups over the previous 24 hours, signalling better micronutrient intake. indicator that captures dietary diversity, a core construct of healthy diets. MDD-W is used to estimate the proportion of non-pregnant women aged 15-49 years who consumed at least five out of ten defined food groups over the previous 24 hours, signalling better micronutrient intake. -- Note that we calculated it as 100% minus the MDD-W (i.e., women not meeting ...) such that higher values correspond with higher potential for impact, | K8: 0.625 | L8: 0.1764 | M8: =D8*5/$I8 -> 4.5730243 | N8: =E8*5/$I8 -> 4.3392685 | O8: =F8*5/$I8 -> 2.826148 | P8: =G8*5/$I8 -> 2.804259 | Q8: =H8*5/$I8 -> 2.6467698 | R8: =I8*5/$I8 -> 5
A9: Gender | B9: Baseline data | C9: Proportion of youth (aged 15-24 years) not in education, employment or training (NEET) (%) | D9: 20.353948 | E9: 28.808683 | F9: 22.22403 | G9: 22.032946 | H9: 25.579269 | I9: 13.900333 | K9: 0.2217 | L9: 0.0531
A10: Gender | B10: Baseline data | C10: Gender Development Index (GDI) | D10: 0.98711807 | E10: 0.86109472 | F10: 0.88128823 | G10: 0.92987576 | H10: 0.85713094 | I10: 0.96249076 | J10: GDI measures gender inequalities in achievement in three basic dimensions of human development: health, measured by female and male life expectancy at birth; education, measured by female and male expected years of schooling for children and female and male mean years of schooling for adults ages 25 years and older; and command over economic resources, measured by female and male estimated earned income. | K10: 1 | L10: 0
A11: Gender | B11: Baseline data | C11: Gender Inequality Index (GII) | D11: 0.3786 | E11: 0.4202 | F11: 0.6154 | G11: 0.51 | H11: 0.4542 | I11: 0.2426 | J11: GII is a composite metric of gender inequality using three dimensions: reproductive health, empowerment and the labour market. A low GII value indicates low inequality between women and men, and vice-versa. | K11: 0.33 | L11: 0.47
A12: Poverty | B12: Baseline data | C12: The ratio of the people employed in agriculture in rural areas over all people employed in rural areas" | D12: 46.830763 | E12: 34.609244 | F12: 64.335138 | G12: 71.949092 | H12: 56.611142 | I12: 44.992877 | K12: 0.5333 | L12: 0.1376
A13: Climate | B13: Baseline data | C13: Vulnerability index of the geography (exposure, sensitivity and adaptive capacity in six life-supporting sectors: food, water, health, ecosystem services, human habitat, and infrastructure). | D13: 0.38522854 | E13: 0.41856096 | F13: 0.52689312 | G13: 0.51707456 | H13: 0.50168331 | I13: 0.40802057 | K13: 0.5 | L13: 0.5
A14: Climate | B14: Baseline data | C14: Emissions intensity - CO2eq emissions from croplands (kg/ha) (Carlson et al., 2017) | D14: 386 | E14: 444 | F14: 312 | G14: 531 | H14: 2090 | I14: 3326 | K14: 1181.5 | L14: 1335.13
A15: Climate | B15: Baseline data | C15: CRI - Climate Risk Index - the index of the level of exposure and vulnerability to extreme events such as storms, floods and heatwaves based on historic data | D15: 46.593083 | E15: 71.63158 | F15: 73.530172 | G15: 45.434032 | H15: 18.194338 | I15: 40.16028 | K15: 49.33 | L15: 19.89
A16: Environment | B16: Baseline data | C16: Consumptive blue and green water used in food production (m3/ha) | D16: 5008.9819 | E16: 3795.1862 | F16: 4064.7898 | G16: 4368.5844 | H16: 5065.8423 | I16: 6113.5583 | K16: 4736.33 | L16: 834.12
A17: Environment | B17: Baseline data | C17: Soil erosion rate (/Ha) | D17: 4480.2558 | E17: 2629.3874 | F17: 5858.9939 | G17: 7924.0507 | H17: 10121.16 | I17: 7076.2489 | K17: 6348.17 | L17: 2682.76
A18: Environment | B18: Baseline data | C18: Forest area lost (%) - the percentage of forested area (%) lost between 2010 and 2020 | D18: 4.0133292 | E18: 3.0328342 | F18: 8.736605 | G18: 6.4758874 | H18: 0.80036497 | I18: 1.9236632 | K18: 0.0417 | L18: 0.0286
A19: Environment | B19: Baseline data | C19: GBI - Global Biodiversity Index - Total number of plant, reptile, mammal, bird, fish and amphibian species | D19: 362.31193 | E19: 80.081948 | F19: 116.18798 | G19: 156.28684 | H19: 264.30093 | I19: 324.04395 | K19: 217 | L19: 118.76
A20: Environment | B20: Baseline data | C20: Sustainable agriculture score - Index quantifying progress toward productive and sustainable agriculture (current status score) | D20: 3.7142926 | E20: 3.0915505 | F20: 3.2533234 | G20: 2.8150793 | H20: 2.5514288 | I20: 3.9867322 | K20: 3.33 | L20: 0.47
A22: Impact Area | B22: Projected to 2040 (without CGIAR intervention) | C22: Indicator | D22: r_lac | X22: r_cwana | AR22: r_wca | BL22: r_esa | CF22: r_sa | CZ22: r_sea
D23: 2021 | E23: 2022 | F23: 2023 | G23: 2024 | H23: 2025 | I23: 2026 | J23: 2027 | K23: 2028 | L23: 2029 | M23: 2030 | N23: 2031 | O23: 2032 | P23: 2033 | Q23: 2034 | R23: 2035 | S23: 2036 | T23: 2037 | U23: 2038 | V23: 2039 | W23: 2040 | X23: 2021 | Y23: 2022 | Z23: 2023 | AA23: 2024 | AB23: 2025 | AC23: 2026 | AD23: 2027 | AE23: 2028 | AF23: 2029 | AG23: 2030 | AH23: 2031 | AI23: 2032 | AJ23: 2033 | AK23: 2034 | AL23: 2035 | AM23: 2036 | AN23: 2037 | AO23: 2038 | AP23: 2039 | AQ23: 2040 | AR23: 2021 | AS23: 2022 | AT23: 2023 | AU23: 2024 | AV23: 2025 | AW23: 2026 | AX23: 2027 | AY23: 2028 | AZ23: 2029 | BA23: 2030 | BB23: 2031 | BC23: 2032 | BD23: 2033 | BE23: 2034 | BF23: 2035 | BG23: 2036 | BH23: 2037 | BI23: 2038 | BJ23: 2039 | BK23: 2040 | BL23: 2021 | BM23: 2022 | BN23: 2023 | BO23: 2024 | BP23: 2025 | BQ23: 2026 | BR23: 2027 | BS23: 2028 | BT23: 2029 | BU23: 2030 | BV23: 2031 | BW23: 2032 | BX23: 2033 | BY23: 2034 | BZ23: 2035 | CA23: 2036 | CB23: 2037 | CC23: 2038 | CD23: 2039 | CE23: 2040 | CF23: 2021 | CG23: 2022 | CH23: 2023 | CI23: 2024 | CJ23: 2025 | CK23: 2026 | CL23: 2027 | CM23: 2028 | CN23: 2029 | CO23: 2030 | CP23: 2031 | CQ23: 2032 | CR23: 2033 | CS23: 2034 | CT23: 2035 | CU23: 2036 | CV23: 2037 | CW23: 2038 | CX23: 2039 | CY23: 2040 | CZ23: 2021 | DA23: 2022 | DB23: 2023 | DC23: 2024 | DD23: 2025 | DE23: 2026 | DF23: 2027 | DG23: 2028 | DH23: 2029 | DI23: 2030 | DJ23: 2031 | DK23: 2032 | DL23: 2033 | DM23: 2034 | DN23: 2035 | DO23: 2036 | DP23: 2037 | DQ23: 2038 | DR23: 2039 | DS23: 2040
A24: Nutrition | B24: Projected to 2040 | C24: Prevalence of Undernourishment - Share of total population living below the minimum calorie daily threshold | D24: 7.1892578 | E24: 6.68889 | F24: 6.2115266 | G24: 5.7570393 | H24: 5.3252329 | I24: 4.9158466 | J24: 4.5285569 | K24: 4.1629803 | L24: 3.8186764 | M24: 3.4951517 | N24: 3.1918631 | O24: 2.908223 | P24: 2.6436027 | Q24: 2.3973382 | R24: 2.1687341 | S24: 1.9570691 | T24: 1.7616009 | U24: 1.5815713 | V24: 1.4162109 | W24: 1.2647443 | X24: 9.1504665 | Y24: 8.9091662 | Z24: 8.6634743 | AA24: 8.4138444 | AB24: 8.160744 | AC24: 7.9046538 | AD24: 7.6460667 | AE24: 7.3854859 | AF24: 7.123424 | AG24: 6.8604013 | AH24: 6.5969443 | AI24: 6.3335834 | AJ24: 6.0708516 | AK24: 5.809282 | AL24: 5.5494058 | AM24: 5.2917502 | AN24: 5.0368357 | AO24: 4.7851739 | AP24: 4.537265 | AQ24: 4.2935953 | AR24: 18.91209 | AS24: 18.415278 | AT24: 17.911492 | AU24: 17.401678 | AV24: 16.886799 | AW24: 16.367828 | AX24: 15.845748 | AY24: 15.321548 | AZ24: 14.796218 | BA24: 14.270749 | BB24: 13.746128 | BC24: 13.223332 | BD24: 12.703327 | BE24: 12.187064 | BF24: 11.675475 | BG24: 11.169467 | BH24: 10.669921 | BI24: 10.177686 | BJ24: 9.6935781 | BK24: 9.2183741 | BL24: 22.510157 | BM24: 21.490211 | BN24: 20.474437 | BO24: 19.465188 | BP24: 18.464847 | BQ24: 17.475809 | BR24: 16.500465 | BS24: 15.541184 | BT24: 14.600291 | BU24: 13.680052 | BV24: 12.782652 | BW24: 11.910171 | BX24: 11.064571 | BY24: 10.247669 | BZ24: 9.4611245 | CA24: 8.7064163 | CB24: 7.9848318 | CC24: 7.2974499 | CD24: 6.645131 | CE24: 6.0285075 | CF24: 15.036352 | CG24: 13.50078 | CH24: 12.058387 | CI24: 10.711231 | CJ24: 9.460449 | CK24: 8.306251 | CL24: 7.2479364 | CM24: 6.2839238 | CN24: 5.4118015 | CO24: 4.6283937 | CP24: 3.9298411 | CQ24: 3.3116949 | CR24: 2.76902 | CS24: 2.2965049 | CT24: 1.8885759 | CU24: 1.53951 | CV24: 1.2435457 | CW24: 0.99498599 | CX24: 0.78829295 | CY24: 0.6181697 | CZ24: 2.9870488 | DA24: 2.5739841 | DB24: 2.2066181 | DC24: 1.8817105 | DD24: 1.5959854 | DE24: 1.3461739 | DF24: 1.1290543 | DG24: 0.94148797 | DH24: 0.78045059 | DI24: 0.64305899 | DJ24: 0.52659245 | DK24: 0.42850921 | DL24: 0.34645781 | DM24: 0.27828373 | DN24: 0.2220316 | DO24: 0.1759435 | DP24: 0.13845375 | DQ24: 0.10818092 | DR24: 0.083917403 | DS24: 0.06461742
A25: Gender | B25: WE CURRENTLY DON’T HAVE APPROPRIATE INDICATORS PROJECTED FOR THE GENDER IMPACT AREA - PLEASE USE BASELINE DATA ONLY
A26: Poverty | B26: Projected to 2040 | C26: Poverty Headcount Rate ($2.15) - Share of total population living below the poverty line | D26: 4.98557 | E26: 5.0242558 | F26: 5.0621172 | G26: 5.0991222 | H26: 5.1352386 | I26: 5.1704341 | J26: 5.2046757 | K26: 5.2379303 | L26: 5.2701643 | M26: 5.3013441 | N26: 5.3314354 | O26: 5.3604039 | P26: 5.3882149 | Q26: 5.4148334 | R26: 5.4402242 | S26: 5.4643519 | T26: 5.4871807 | U26: 5.5086747 | V26: 5.5287977 | W26: 5.5475134 | X26: 4.59918 | Y26: 4.4042124 | Z26: 4.2131091 | AA26: 4.02598 | AB26: 3.84293 | AC26: 3.6640582 | AD26: 3.4894579 | AE26: 3.319216 | AF26: 3.1534129 | AG26: 2.9921218 | AH26: 2.8354089 | AI26: 2.6833326 | AJ26: 2.5359435 | AK26: 2.3932841 | AL26: 2.2553884 | AM26: 2.1222821 | AN26: 1.9939817 | AO26: 1.8704952 | AP26: 1.7518213 | AQ26: 1.6379496 | AR26: 36.30807 | AS26: 36.185862 | AT26: 36.061701 | AU26: 35.935577 | AV26: 35.807479 | AW26: 35.677395 | AX26: 35.545315 | AY26: 35.411226 | AZ26: 35.275116 | BA26: 35.136975 | BB26: 34.996788 | BC26: 34.854543 | BD26: 34.710229 | BE26: 34.56383 | BF26: 34.415335 | BG26: 34.26473 | BH26: 34.112002 | BI26: 33.957135 | BJ26: 33.800117 | BK26: 33.640934 | BL26: 38.89568 | BM26: 38.85434 | BN26: 38.811608 | BO26: 38.767445 | BP26: 38.721807 | BQ26: 38.674652 | BR26: 38.625933 | BS26: 38.575602 | BT26: 38.523611 | BU26: 38.469907 | BV26: 38.414438 | BW26: 38.357148 | BX26: 38.297978 | BY26: 38.236869 | BZ26: 38.173758 | CA26: 38.10858 | CB26: 38.041268 | CC26: 37.97175 | CD26: 37.899953 | CE26: 37.825801 | CF26: 11.48274 | CG26: 10.469358 | CH26: 9.4825203 | CI26: 8.5274757 | CJ26: 7.6094386 | CK26: 6.7334754 | CL26: 5.904376 | CM26: 5.126516 | CN26: 4.4037126 | CO26: 3.7390816 | CP26: 3.134903 | CQ26: 2.5925037 | CR26: 2.1121683 | CS26: 1.6930861 | CT26: 1.3333448 | CU26: 1.0299761 | CV26: 0.77905634 | CW26: 0.57586239 | CX26: 0.41507324 | CY26: 0.29100712 | CZ26: 1.23059 | DA26: 0.88984793 | DB26: 0.6221891 | DC26: 0.41911725 | DD26: 0.27092336 | DE26: 0.16738356 | DF26: 0.098482932 | DG26: 0.055066945 | DH26: 0.029330068 | DI26: 0.015081471 | DJ26: 0.0077742847 | DK26: 0.0043346014 | DL26: 0.0028635352 | DM26: 0.0022984445 | DN26: 0.0021059525 | DO26: 0.0020486343 | DP26: 0.0020339519 | DQ26: 0.002030774 | DR26: 0.0020302043 | DS26: 0.0020301216
A27: Poverty | B27: Projected to 2040 | C27: Poverty Headcount Rate ($3.65) - Share of total population living below the poverty line | D27: 12.326178 | E27: 12.381889 | F27: 12.436252 | G27: 12.489232 | H27: 12.540798 | I27: 12.590913 | J27: 12.639544 | K27: 12.686654 | L27: 12.732209 | M27: 12.776171 | N27: 12.818504 | O27: 12.85917 | P27: 12.898132 | Q27: 12.935351 | R27: 12.970787 | S27: 13.004401 | T27: 13.036154 | U27: 13.066003 | V27: 13.093907 | W27: 13.119826 | X27: 14.288423 | Y27: 13.982703 | Z27: 13.67684 | AA27: 13.370967 | AB27: 13.065221 | AC27: 12.759739 | AD27: 12.454666 | AE27: 12.150146 | AF27: 11.846328 | AG27: 11.543362 | AH27: 11.241404 | AI27: 10.940608 | AJ27: 10.641135 | AK27: 10.343146 | AL27: 10.046804 | AM27: 9.7522739 | AN27: 9.4597232 | AO27: 9.1693202 | AP27: 8.8812344 | AQ27: 8.5956364 | AR27: 64.127509 | AS27: 64.124548 | AT27: 64.121536 | AU27: 64.118473 | AV27: 64.115359 | AW27: 64.112192 | AX27: 64.108972 | AY27: 64.105699 | AZ27: 64.102372 | BA27: 64.098991 | BB27: 64.095554 | BC27: 64.092063 | BD27: 64.088515 | BE27: 64.08491 | BF27: 64.081248 | BG27: 64.077527 | BH27: 64.073748 | BI27: 64.06991 | BJ27: 64.066011 | BK27: 64.062051 | BL27: 65.516569 | BM27: 65.515305 | BN27: 65.513998 | BO27: 65.512647 | BP27: 65.511251 | BQ27: 65.509807 | BR27: 65.508315 | BS27: 65.506774 | BT27: 65.50518 | BU27: 65.503534 | BV27: 65.501833 | BW27: 65.500075 | BX27: 65.498258 | BY27: 65.496382 | BZ27: 65.494442 | CA27: 65.492439 | CB27: 65.490368 | CC27: 65.488229 | CD27: 65.486018 | CE27: 65.483733 | CF27: 43.13417 | CG27: 42.785936 | CH27: 42.423103 | CI27: 42.045096 | CJ27: 41.651323 | CK27: 41.241181 | CL27: 40.814053 | CM27: 40.369309 | CN27: 39.906311 | CO27: 39.424414 | CP27: 38.922966 | CQ27: 38.401314 | CR27: 37.858808 | CS27: 37.294802 | CT27: 36.708661 | CU27: 36.099766 | CV27: 35.467522 | CW27: 34.811364 | CX27: 34.130765 | CY27: 33.425246 | CZ27: 6.6233529 | DA27: 5.5934126 | DB27: 4.6450586 | DC27: 3.7861739 | DD27: 3.0226307 | DE27: 2.3578335 | DF27: 1.7923687 | DG27: 1.323821 | DH27: 0.94680861 | DI27: 0.65326964 | DJ27: 0.43300161 | DK27: 0.2744137 | DL27: 0.16540941 | DM27: 0.094283044 | DN27: 0.050501138 | DO27: 0.025256507 | DP27: 0.011729008 | DQ27: 0.0050518673 | DR27: 0.0020459537 | DS27: 0.00082542745
A28: Poverty | B28: Projected to 2040 | C28: Poverty Headcount Rate ($6.85) - Share of total population living below the poverty line | D28: 31.99797 | E28: 32.039063 | F28: 32.079058 | G28: 32.117939 | H28: 32.155689 | I28: 32.192292 | J28: 32.227729 | K28: 32.261984 | L28: 32.295038 | M28: 32.326872 | N28: 32.357466 | O28: 32.386801 | P28: 32.414856 | Q28: 32.441611 | R28: 32.467043 | S28: 32.491131 | T28: 32.513851 | U28: 32.535181 | V28: 32.555096 | W28: 32.573571 | X28: 39.779017 | Y28: 39.643681 | Z28: 39.506381 | AA28: 39.367094 | AB28: 39.225797 | AC28: 39.082466 | AD28: 38.937077 | AE28: 38.789605 | AF28: 38.640025 | AG28: 38.488313 | AH28: 38.334443 | AI28: 38.178388 | AJ28: 38.020124 | AK28: 37.859624 | AL28: 37.69686 | AM28: 37.531806 | AN28: 37.364435 | AO28: 37.194718 | AP28: 37.022628 | AQ28: 36.848136 | AR28: 88.509867 | AS28: 88.506906 | AT28: 88.503894 | AU28: 88.500831 | AV28: 88.497716 | AW28: 88.494549 | AX28: 88.49133 | AY28: 88.488056 | AZ28: 88.48473 | BA28: 88.481348 | BB28: 88.477912 | BC28: 88.47442 | BD28: 88.470872 | BE28: 88.467267 | BF28: 88.463605 | BG28: 88.459885 | BH28: 88.456106 | BI28: 88.452267 | BJ28: 88.448368 | BK28: 88.444408 | BL28: 87.43947 | BM28: 87.438206 | BN28: 87.4369 | BO28: 87.435549 | BP28: 87.434152 | BQ28: 87.432709 | BR28: 87.431217 | BS28: 87.429675 | BT28: 87.428082 | BU28: 87.426435 | BV28: 87.424734 | BW28: 87.422976 | BX28: 87.42116 | BY28: 87.419283 | BZ28: 87.417344 | CA28: 87.41534 | CB28: 87.413269 | CC28: 87.41113 | CD28: 87.408919 | CE28: 87.406634 | CF28: 80.974435 | CG28: 80.959243 | CH28: 80.943388 | CI28: 80.92684 | CJ28: 80.909568 | CK28: 80.891539 | CL28: 80.872719 | CM28: 80.853071 | CN28: 80.832558 | CO28: 80.811141 | CP28: 80.788779 | CQ28: 80.765429 | CR28: 80.741045 | CS28: 80.71558 | CT28: 80.688986 | CU28: 80.66121 | CV28: 80.632198 | CW28: 80.601895 | CX28: 80.57024 | CY28: 80.537172 | CZ28: 29.55282 | DA28: 28.453081 | DB28: 27.310321 | DC28: 26.125513 | DD28: 24.900204 | DE28: 23.636605 | DF28: 22.337679 | DG28: 21.007236 | DH28: 19.650019 | DI28: 18.271781 | DJ28: 16.879345 | DK28: 15.480643 | DL28: 14.084712 | DM28: 12.701646 | DN28: 11.342485 | DO28: 10.019034 | DP28: 8.7435908 | DQ28: 7.528593 | DR28: 6.3861649 | DS28: 5.327589
A29: Poverty | B29: Projected to 2040 | C29: Agrifood System Jobs (incl. subsistence farming and informal sector) - millions of workers | D29: 79.453806 | E29: 81.086566 | F29: 82.7612 | G29: 84.478933 | H29: 86.241033 | I29: 88.048807 | J29: 89.903606 | K29: 91.806824 | L29: 93.759905 | M29: 95.764336 | N29: 97.821657 | O29: 99.933458 | P29: 102.10138 | Q29: 104.32713 | R29: 106.61247 | S29: 108.95919 | T29: 111.3692 | U29: 113.84443 | V29: 116.3869 | W29: 118.99868 | X29: 50.377779 | Y29: 51.475884 | Z29: 52.606947 | AA29: 53.772164 | AB29: 54.972781 | AC29: 56.210098 | AD29: 57.485472 | AE29: 58.800317 | AF29: 60.156109 | AG29: 61.554391 | AH29: 62.996771 | AI29: 64.48493 | AJ29: 66.020625 | AK29: 67.605691 | AL29: 69.242045 | AM29: 70.931693 | AN29: 72.676732 | AO29: 74.479356 | AP29: 76.341859 | AQ29: 78.266643 | AR29: 118.18601 | AS29: 122.23843 | AT29: 126.45317 | AU29: 130.8372 | AV29: 135.39785 | AW29: 140.14274 | AX29: 145.07984 | AY29: 150.21751 | AZ29: 155.56444 | BA29: 161.12976 | BB29: 166.92299 | BC29: 172.9541 | BD29: 179.23348 | BE29: 185.77203 | BF29: 192.58113 | BG29: 199.67268 | BH29: 207.05915 | BI29: 214.75354 | BJ29: 222.76947 | BK29: 231.1212 | BL29: 152.33566 | BM29: 158.07421 | BN29: 164.07237 | BO29: 170.34342 | BP29: 176.90137 | BQ29: 183.76104 | BR29: 190.93808 | BS29: 198.44902 | BT29: 206.31135 | BU29: 214.54355 | BV29: 223.16518 | BW29: 232.19692 | BX29: 241.66066 | BY29: 251.57954 | BZ29: 261.9781 | CA29: 272.88229 | CB29: 284.3196 | CC29: 296.31915 | CD29: 308.91182 | CE29: 322.1303 | CF29: 335.11902 | CG29: 345.66882 | CH29: 356.63814 | CI29: 368.04754 | CJ29: 379.91877 | CK29: 392.27487 | CL29: 405.14024 | CM29: 418.54076 | CN29: 432.50383 | CO29: 447.05854 | CP29: 462.23575 | CQ29: 478.06821 | CR29: 494.5907 | CS29: 511.84016 | CT29: 529.85585 | CU29: 548.6795 | CV29: 568.3555 | CW29: 588.93105 | CX29: 610.45641 | CY29: 632.98506 | CZ29: 430.51747 | DA29: 439.33041 | DB29: 448.38064 | DC29: 457.67536 | DD29: 467.22202 | DE29: 477.02828 | DF29: 487.10209 | DG29: 497.45165 | DH29: 508.08544 | DI29: 519.0122 | DJ29: 530.24097 | DK29: 541.7811 | DL29: 553.64225 | DM29: 565.8344 | DN29: 578.36786 | DO29: 591.25328 | DP29: 604.5017 | DQ29: 618.12449 | DR29: 632.13342 | DS29: 646.54069
A30: Poverty | B30: Projected to 2040 | C30: Agrifood System GDP Per Worker - US$ per worker | D30: 9757.9382 | E30: 9757.9382 | F30: 9757.9382 | G30: 9757.9382 | H30: 9757.9382 | I30: 9757.9382 | J30: 9757.9382 | K30: 9757.9382 | L30: 9757.9382 | M30: 9757.9382 | N30: 9757.9382 | O30: 9757.9382 | P30: 9757.9382 | Q30: 9757.9382 | R30: 9757.9382 | S30: 9757.9382 | T30: 9757.9382 | U30: 9757.9382 | V30: 9757.9382 | W30: 9757.9382 | X30: 11320.812 | Y30: 11320.812 | Z30: 11320.812 | AA30: 11320.812 | AB30: 11320.812 | AC30: 11320.812 | AD30: 11320.812 | AE30: 11320.812 | AF30: 11320.812 | AG30: 11320.812 | AH30: 11320.812 | AI30: 11320.812 | AJ30: 11320.812 | AK30: 11320.812 | AL30: 11320.812 | AM30: 11320.812 | AN30: 11320.812 | AO30: 11320.812 | AP30: 11320.812 | AQ30: 11320.812 | AR30: 2860.2434 | AS30: 2860.2434 | AT30: 2860.2434 | AU30: 2860.2434 | AV30: 2860.2434 | AW30: 2860.2434 | AX30: 2860.2434 | AY30: 2860.2434 | AZ30: 2860.2434 | BA30: 2860.2434 | BB30: 2860.2434 | BC30: 2860.2434 | BD30: 2860.2434 | BE30: 2860.2434 | BF30: 2860.2434 | BG30: 2860.2434 | BH30: 2860.2434 | BI30: 2860.2434 | BJ30: 2860.2434 | BK30: 2860.2434 | BL30: 1686.5692 | BM30: 1686.5692 | BN30: 1686.5692 | BO30: 1686.5692 | BP30: 1686.5692 | BQ30: 1686.5692 | BR30: 1686.5692 | BS30: 1686.5692 | BT30: 1686.5692 | BU30: 1686.5692 | BV30: 1686.5692 | BW30: 1686.5692 | BX30: 1686.5692 | BY30: 1686.5692 | BZ30: 1686.5692 | CA30: 1686.5692 | CB30: 1686.5692 | CC30: 1686.5692 | CD30: 1686.5692 | CE30: 1686.5692 | CF30: 2772.7337 | CG30: 2772.7337 | CH30: 2772.7337 | CI30: 2772.7337 | CJ30: 2772.7337 | CK30: 2772.7337 | CL30: 2772.7337 | CM30: 2772.7337 | CN30: 2772.7337 | CO30: 2772.7337 | CP30: 2772.7337 | CQ30: 2772.7337 | CR30: 2772.7337 | CS30: 2772.7337 | CT30: 2772.7337 | CU30: 2772.7337 | CV30: 2772.7337 | CW30: 2772.7337 | CX30: 2772.7337 | CY30: 2772.7337 | CZ30: 8556.862 | DA30: 8556.862 | DB30: 8556.862 | DC30: 8556.862 | DD30: 8556.862 | DE30: 8556.862 | DF30: 8556.862 | DG30: 8556.862 | DH30: 8556.862 | DI30: 8556.862 | DJ30: 8556.862 | DK30: 8556.862 | DL30: 8556.862 | DM30: 8556.862 | DN30: 8556.862 | DO30: 8556.862 | DP30: 8556.862 | DQ30: 8556.862 | DR30: 8556.862 | DS30: 8556.862
A31: Climate | B31: Projected to 2040 | C31: Agrifood System Greenhouse Gas (GHG) Emissions | D31: 1290.6349 | E31: 1299.4607 | F31: 1308.4565 | G31: 1317.627 | H31: 1326.977 | I31: 1336.5113 | J31: 1346.2348 | K31: 1356.1529 | L31: 1366.2709 | M31: 1376.5942 | N31: 1387.1287 | O31: 1397.8802 | P31: 1408.8548 | Q31: 1420.0587 | R31: 1431.4986 | S31: 1443.181 | T31: 1455.113 | U31: 1467.3017 | V31: 1479.7545 | W31: 1492.4791 | X31: 521.24598 | Y31: 532.37733 | Z31: 543.82156 | AA31: 555.58869 | AB31: 567.68908 | AC31: 580.13348 | AD31: 592.93304 | AE31: 606.09934 | AF31: 619.64439 | AG31: 633.58065 | AH31: 647.92106 | AI31: 662.67905 | AJ31: 677.86859 | AK31: 693.50417 | AL31: 709.60086 | AM31: 726.17432 | AN31: 743.24082 | AO31: 760.81729 | AP31: 778.92133 | AQ31: 797.57126 | AR31: 420.59141 | AS31: 431.825 | AT31: 443.40263 | AU31: 455.3357 | AV31: 467.63605 | AW31: 480.31594 | AX31: 493.38808 | AY31: 506.86563 | AZ31: 520.76222 | BA31: 535.09201 | BB31: 549.86963 | BC31: 565.11028 | BD31: 580.82972 | BE31: 597.04426 | BF31: 613.77085 | BG31: 631.02704 | BH31: 648.83104 | BI31: 667.20175 | BJ31: 686.15877 | BK31: 705.72241 | BL31: 552.78648 | BM31: 575.08538 | BN31: 598.466 | BO31: 622.98755 | BP31: 648.71274 | BQ31: 675.70795 | BR31: 704.0435 | BS31: 733.79384 | BT31: 765.03783 | BU31: 797.85902 | BV31: 832.34591 | BW31: 868.59228 | BX31: 906.69748 | BY31: 946.76683 | BZ31: 988.91191 | CA31: 1033.251 | CB31: 1079.9095 | CC31: 1129.0204 | CD31: 1180.7245 | CE31: 1235.1714 | CF31: 1337.1419 | CG31: 1368.6614 | CH31: 1401.2786 | CI31: 1435.0419 | CJ31: 1470.0024 | CK31: 1506.2136 | CL31: 1543.732 | CM31: 1582.6166 | CN31: 1622.9297 | CO31: 1664.7367 | CP31: 1708.1063 | CQ31: 1753.1111 | CR31: 1799.8271 | CS31: 1848.3343 | CT31: 1898.7173 | CU31: 1951.0646 | CV31: 2005.4699 | CW31: 2062.0314 | CX31: 2120.8529 | CY31: 2182.0435 | CZ31: 2408.5001 | DA31: 2440.4414 | DB31: 2473.2397 | DC31: 2506.9196 | DD31: 2541.5063 | DE31: 2577.0259 | DF31: 2613.5052 | DG31: 2650.9722 | DH31: 2689.4553 | DI31: 2728.9842 | DJ31: 2769.5894 | DK31: 2811.3024 | DL31: 2854.1556 | DM31: 2898.1827 | DN31: 2943.4182 | DO31: 2989.8979 | DP31: 3037.6588 | DQ31: 3086.7389 | DR31: 3137.1777 | DS31: 3189.0156
A34: Prevalence of Undernourishment
A52: Undernourished Population
A69: Poverty Headcount Rate ($2.15)
A85: Poverty Headcount Rate ($3.65)
A102: Poverty Headcount Rate ($6.85)
A119: Agrifood System Jobs (incl. subsistence farming and informal sector)
A137: Agricultural Jobs (incl. subsistence farming and informal sector)
A154: Agricultural Greenhouse Gas (GHG) Emissions

Sheet 1.Food_security
C1: FS Indicators
A2: VH | B2: 5 | D2: LAC | E2: CWANA | F2: WCA | G2: ESA | H2: SA | I2: SEA
A3: H | B3: 4 | C3: Total score by column | D3: =SUM(D11:D49) -> 34 | E3: =SUM(E11:E49) -> 34 | F3: =SUM(F11:F49) -> 41 | G3: =SUM(G11:G49) -> 41 | H3: =SUM(H11:H49) -> 48 | I3: =SUM(I11:I49) -> 34
A4: MH | B4: 3 | C4: VH count by column | D4: =COUNTIF(D$11:D$49, 5) -> 0 | E4: =COUNTIF(E$11:E$49, 5) -> 0 | F4: =COUNTIF(F$11:F$49, 5) -> 0 | G4: =COUNTIF(G$11:G$49, 5) -> 0 | H4: =COUNTIF(H$11:H$49, 5) -> 3 | I4: =COUNTIF(I$11:I$49, 5) -> 0
A5: M | B5: 2 | C5: H count by column | D5: =COUNTIF(D$11:D$49, 4) -> 3 | E5: =COUNTIF(E$11:E$49, 4) -> 3 | F5: =COUNTIF(F$11:F$49, 4) -> 3 | G5: =COUNTIF(G$11:G$49, 4) -> 3 | H5: =COUNTIF(H$11:H$49, 4) -> 3 | I5: =COUNTIF(I$11:I$49, 4) -> 3
A6: L | B6: 1 | C6: MH count by column | D6: =COUNTIF(D$11:D$49, 3) -> 3 | E6: =COUNTIF(E$11:E$49, 3) -> 3 | F6: =COUNTIF(F$11:F$49, 3) -> 6 | G6: =COUNTIF(G$11:G$49, 3) -> 6 | H6: =COUNTIF(H$11:H$49, 3) -> 4 | I6: =COUNTIF(I$11:I$49, 3) -> 3
C7: M count by column | D7: =COUNTIF(D$11:D$49, 2) -> 4 | E7: =COUNTIF(E$11:E$49, 2) -> 4 | F7: =COUNTIF(F$11:F$49, 2) -> 5 | G7: =COUNTIF(G$11:G$49, 2) -> 5 | H7: =COUNTIF(H$11:H$49, 2) -> 4 | I7: =COUNTIF(I$11:I$49, 2) -> 4
C8: L count by column | D8: =COUNTIF(D$11:D$49, 1) -> 5 | E8: =COUNTIF(E$11:E$49, 1) -> 5 | F8: =COUNTIF(F$11:F$49, 1) -> 1 | G8: =COUNTIF(G$11:G$49, 1) -> 1 | H8: =COUNTIF(H$11:H$49, 1) -> 1 | I8: =COUNTIF(I$11:I$49, 1) -> 5 | K8: Current state (across the Global South) | L8: Ideal state (across the Global South) | M8: Assumptions (for region-specific scores) | N8: Requirements for success (internal to P/A) | O8: Requirements for success (from other P/As) | P8: Regional Implication
C10: HLO | D10: LAC | E10: CWANA | F10: WCA | G10: ESA | H10: SA | I10: SEA
A11: HLO count: | B11: =COUNTA(C11:C49) -> 15 | C11: =HLOs!D8 -> HLO 1.1.1: Demand signaling | D11: 4 | E11: 4 | F11: 4 | G11: 4 | H11: 5 | I11: 4 | K11: Existing demand signaling systems for food security are fragmented, poorly institutionalized, and largely reactive. Most mechanisms operate in silos—within projects or national programs—without a coordinated structure to capture or aggregate regional scaling needs. As a result, innovation and investment decisions often lack grounding in localized food insecurity drivers or emergent farmer and market demands (FAO, 2021; Wigboldus et al., 2016). | L11: Integrated, anticipatory demand signaling systems that are regionally coordinated, data-informed, and driven by farmer and market needs. These systems enable continuous identification and prioritization of innovations based on evolving food security challenges and scaling opportunities. They combine participatory inputs with digital infrastructure and foresight tools to guide investment and policy decisions across CGIAR and national systems (FAO & WEF, 2022). | M11: Higher regional scores indicate weak or absent mechanisms to systematically capture and prioritize local innovation and scaling demands related to food security. This includes the absence of interoperable data systems, low institutional capacity to aggregate grassroots needs, and limited coordination among research, policy, and implementation actors (Gálvez, 2022; CGIAR, 2023; Schut et al., 2024). | N11: Within CGIAR, success requires the development and institutionalization of participatory platforms that enable systematic capture of farmer, partner, and market signals across geographies. This must be coupled with the integration of real-time, interoperable data systems across Initiatives and Centers to ensure that regional scaling demands are continuously monitored, shared, and fed into research prioritization and innovation pipelines (CGIAR GENDER Impact Platform, 2023). | O11: Collaborate with ministries, ICT actors, and farmer groups to design and maintain real-time, inclusive platforms for demand articulation and foresight analytics (FAO & ITU, 2022). National research agencies and digital service providers must be engaged to operationalize subnational data layers and innovation targeting. | P11: SA and ESA scored highest for this HLO (Table 1), indicating strong relevance due to persistent food insecurity and undernutrition alongside weak regional innovation targeting. WCA also showed moderate priority. Investment in structured demand articulation systems—including digital tools and participatory platforms—is critical in these regions to align CGIAR innovation pipelines with ground-level needs and reduce misallocation of scaling efforts.
A12: Sets of 5: | B12: =_xlfn.FLOOR.MATH(B11/5) -> 3 | C12: =HLOs!D9 -> HLO 1.1.2: Feedback and adaptive research and scaling prioritization | D12: 3 | E12: 3 | F12: 3 | G12: 3 | H12: 4 | I12: 3 | K12: Feedback loops between agricultural research and the realities of farmers, markets, and local food systems remain weak, slow, and inconsistently applied. While some CGIAR Initiatives integrate field-based learning into research prioritization, these practices are not systematically institutionalized across regions. Most mechanisms rely on end-of-project evaluations or disconnected surveys, lacking real-time learning channels that could dynamically inform research pipelines and scaling priorities. This delay undermines the adaptability and local relevance of food system innovations (World Bank, 2020). | L12: Well-functioning, iterative feedback systems are embedded within CGIAR’s research and scaling processes. These systems capture insights from field implementation, extension networks, farmer groups, and partners in real time, and use them to continuously update research priorities and refine scaling strategies. The ideal state enables two-way learning—between science and practice—grounded in region-specific food security challenges. (Pingali & Aiyar, 2022). | M12: Higher scores reflect the need to institutionalize adaptive research systems, especially in WCA and ESA, where informal feedback channels are not supported by digital tools or policy linkages. SA shows early progress due to established CGIAR presence and stronger research-extension interfaces. Assumes real-time feedback is essential to prevent mismatched innovations and improve scale-readiness (Gálvez, 2022; CGIAR, 2023; Schut et al., 2024). | N12: Institutionalize real-time, adaptive monitoring and learning (MEL) systems across CGIAR research-for-development projects. These should include structured feedback loops, scaling readiness indicators, and dynamic dashboards. Support capacity building of researchers and MEL staff in adaptive management (Douthwaite & Hoffecker, 2017). | O12: Build partnerships with national extension systems, cooperatives, and innovation intermediaries that can relay implementation-level data and enable rapid adjustment of CGIAR’s scaling approaches. Align feedback systems with government M&E platforms to enhance uptake of recommendations (Anderson et al., 2020). | P12: SA, ESA, and WCA scored highest for this HLO, reflecting the urgency to embed feedback loops into innovation scaling. While SA demonstrates relative progress, ESA and WCA face significant feedback fragmentation and limited responsiveness. These regions require support to establish digital feedback infrastructure and partnerships that enable dynamic prioritization and realignment of scaling pipelines with localized food security conditions.
A13: Remainder: | B13: =MOD(B11,5) -> 0 | C13: =HLOs!D10 -> HLO 1.1.3: Enhance strategies and coordination | D13: 2 | E13: 2 | F13: 3 | G13: 3 | H13: 3 | I13: 2 | K13: While numerous food security strategies exist at national and regional levels, coordination across actors—government agencies, CGIAR centers, donors, NGOs, and private sector—is often weak or inconsistent. Many initiatives operate in parallel, resulting in duplication of efforts, fragmented resource use, and reduced impact. Strategic planning tends to be top-down and project-driven, rather than co-developed across systems. Sectoral silos—between agriculture, health, nutrition, and climate—further hinder integrated responses to food insecurity (OECD, 2021). | L13: A coherent, multi-actor strategic framework exists to guide system-level food security transformation through aligned priorities, investments, and delivery mechanisms. CGIAR and national actors co-develop and implement strategies that span research, policy, and implementation levels. These are dynamic, learning-oriented, and grounded in cross-sector coordination, fostering joint ownership across stakeholders (HLPE, 2020). | M13: High scores in SA and WCA indicate weak institutional coordination, where overlapping mandates and under-resourced coordination platforms limit integrated strategy implementation. ESA faces similar challenges. It is assumed that addressing fragmentation will improve program effectiveness and enable alignment between food production, access, and nutrition goals (FAO, 2022). | N13: CGIAR must co-develop cross-Initiative strategies with clear alignment mechanisms, shared performance metrics, and learning loops. Strengthen internal convening roles at regional levels to ensure unified delivery on food security objectives across Centers and Initiatives (CGIAR, 2022). | O13: National governments and regional organizations should activate or strengthen formal coordination platforms that bring together agriculture, health, climate, and food security stakeholders. Development partners must align their support with nationally led strategies and invest in joint planning, reviews, and accountability mechanisms (UNESCAP, 2023). | P13: SA and WCA are top priorities, with ESA also requiring action. These regions exhibit fragmented institutional ecosystems, limiting joint planning and delivery. Strengthening coordination mechanisms—both within CGIAR and externally—is vital for scaling food security innovations. Joint strategy development, inter-agency taskforces, and harmonized investment frameworks can help bridge current silos and amplify system-wide outcomes.
A14: Max score: | B14: =(B12*SUM($B$2:$B$6))+IF(B11=0,0,SUM($B$2:INDEX(B:B,$B$13+1))) -> 50 | C14: =HLOs!D11 -> HLO 2.2.1: Innovation networks enhance agrifood system solution scaling | D14: 1 | E14: 1 | F14: 1 | G14: 1 | H14: 1 | I14: 1 | K14: Innovation networks in the agrifood sector remain underdeveloped across most regions, especially where institutional and private sector capacity is limited. Existing linkages between CGIAR and local actors—such as farmer organizations, ag-tech startups, and extension agencies—are fragmented and project-dependent. Platforms intended to support innovation co-creation often lack sustainability, funding, and inclusion of market actors. As a result, promising food security solutions remain isolated and poorly scaled (Davis et al., 2023). | L14: A dynamic and inclusive innovation ecosystem exists in which CGIAR, national research systems, local innovators, and private sector actors collaborate to co-develop and scale food system solutions. These networks are supported by dedicated hubs, digital platforms, and financing mechanisms that enable rapid piloting, feedback, and adaptation. Innovation networks operate not only within countries but also across borders to respond to region-specific food security challenges (World Bank, 2024). | M14: Although innovation networks across regions remain weak, the uniformly low scores for this HLO in the KBP exercise suggest that—relative to other Food Security HLOs—this area currently offers limited strategic leverage for near-term scaling. It is assumed that strengthening networks without parallel improvements in demand signaling, bundling, and enabling policy environments will not deliver substantial short-term returns (Gálvez, 2022; CGIAR, 2023; Schut et al., 2024). | N14: CGIAR should prioritize foundational efforts such as mapping innovation actors, identifying coordination gaps, and building early-stage partnerships across Initiatives and Centers. A lean, learning-oriented approach that emphasizes institutional readiness, ecosystem diagnostics, and piloting innovation brokerage mechanisms is appropriate at this stage (van Rijn et al., 2020). | O14: Externally, CGIAR should selectively engage with innovation intermediaries, incubators, and regional platforms that are already facilitating agricultural innovation. Rather than creating new structures, partnerships should reinforce existing national systems and support inclusive participation by farmer groups, women, and youth innovators (FAO, 2021). | P14: This HLO received the lowest prioritization across all regions in the KBP. While SA, ESA, and WCA face weak innovation ecosystems, other HLOs—such as demand signaling and bundling—are more urgent entry points for food security scaling. In these regions, innovation network investments should remain exploratory and diagnostic, preparing the ground for deeper engagement once enabling conditions are strengthened.
C15: =HLOs!D12 -> HLO 2.2.2: Methods evaluating agrifood system solutions for scale | D15: 1 | E15: 1 | F15: 2 | G15: 2 | H15: 2 | I15: 1 | K15: Evaluation methods used to assess the scalability of agrifood system innovations are largely ad hoc, inconsistent across programs, and often introduced only at the end of the project cycle. There is limited use of prospective tools or metrics that assess whether innovations are socially, economically, and institutionally scalable in diverse contexts. This results in missed opportunities to adapt innovations early or avoid scaling solutions that lack contextual fit or stakeholder ownership (Rogers et al., 2021). | L15: A robust and standardized suite of methods is available and routinely used across CGIAR programs to assess the scalability of agrifood innovations. These methods are applied early and iteratively throughout the innovation and scaling process, incorporating system dynamics, contextual fit, stakeholder engagement, and long-term sustainability considerations. Scalability assessments are embedded within CGIAR’s adaptive management frameworks, enabling more effective decision-making on investment and scale-out (Wigboldus, 2018). | M15: The KBP results indicate that SA and ESA have begun to apply basic scalability diagnostics, but institutional uptake remains partial and uncoordinated. In contrast, WCA and SEA lag behind due to limited evaluation capacity and disconnected research and scaling teams. Scores reflect both demand for improved methods and current institutional gaps (Gálvez, 2022; CGIAR, 2023; Schut et al., 2024). | N15: Internally, CGIAR must develop and institutionalize evaluation toolkits for scaling, integrated into project design and MEL systems. Capacity development is needed for research teams and MELIA specialists to use these tools and feed insights into adaptive decision-making. Tools should be designed for both formative and summative evaluation stages (Glover et al., 2019). | O15: Externally, CGIAR should partner with academic institutions, think tanks, and independent evaluators to validate methods and support uptake. Public and private sector stakeholders must be trained to interpret scalability assessments and apply them in investment decisions. Donor alignment with evidence-based scaling frameworks will be critical (IFPRI, 2023). | P15: SA, ESA, and WCA show high alignment with this HLO and should be prioritized for the rollout of new methods. These regions face intense pressure to deliver scalable solutions to food insecurity, and improved evaluation will enhance targeting, efficiency, and equity of CGIAR innovation portfolios. Investment in these regions will improve scale-readiness and support systemic learning.
C16: =HLOs!D13 -> HLO 2.2.3: Scale-ready agrifood system solution bundles and packages | D16: 3 | E16: 3 | F16: 3 | G16: 3 | H16: 4 | I16: 3 | K16: Agrifood system innovations are often delivered in isolation—such as improved seed varieties, digital tools, or training modules—rather than as cohesive, mutually reinforcing packages. Where bundling exists, it tends to be inconsistent, poorly contextualized, and disconnected from farmer realities or market ecosystems. This undermines scalability and sustainability, as individual components often fail without complementary inputs like finance, policy support, or behavior change strategies (Herrero et al., 2021). | L16: Integrated, locally adapted innovation bundles that respond to farmer typologies and agroecological contexts, combining technological, institutional, and service innovations. These bundles are co-developed with users and market actors and aligned with delivery systems to ensure adoption at scale. CGIAR Initiatives and national partners share tools and processes for bundling that reflect local realities and system interdependencies (Gálvez, 2022; CGIAR, 2023; Schut et al., 2024). | M16: High prioritization scores for this HLO in SA, ESA, and WCA reflect critical gaps in integrated delivery of solutions. It is assumed that while multiple innovations are being promoted, their lack of contextual bundling hinders adoption and sustained use. The need for bundling is particularly high in SA, where input-output-market linkages remain fragmented, and in ESA and WCA, where capacity to package innovations with services and policy support is limited (FAO, 2022). | N16: CGIAR must develop bundling protocols across Initiatives, ensuring that research outputs are integrated into locally adapted solution packages. This includes working across themes (e.g., seed systems, digital, finance) and aligning bundling with agroecological and livelihood typologies. Initiatives should pilot and refine bundled approaches in diverse contexts, using feedback from users to iterate on content and delivery (HLPE, 2020). | O16: Collaborations with private sector actors, cooperatives, NGOs, and government extension services are essential to co-design, deliver, and refine bundled packages. These actors bring insights into user preferences, cost structures, and delivery logistics. Market incentives and policy support mechanisms (e.g., subsidies or extension platforms) must be aligned to encourage bundle uptake (Anderson et al., 2020). | P16: SA, ESA, and WCA are high-priority regions for bundling due to their diverse production systems, high levels of input-output fragmentation, and limited adoption of standalone innovations. Bundling offers an efficient entry point to improve food security outcomes by aligning technical solutions with farmers’ contextual realities. Investments in these regions should prioritize co-design of bundles with farmers and integration into broader delivery systems.
C17: =HLOs!D14 -> HLO 2.2.4: Agrifood system solution scaling strategies | D17: 4 | E17: 4 | F17: 4 | G17: 4 | H17: 5 | I17: 4 | K17: Current scaling efforts are fragmented, project-driven, and rarely embedded within national or regional food system transformation strategies. CGIAR programs often lack long-term, system-level scaling pathways. Where strategies exist, they tend to focus on technology dissemination rather than system integration or sustainability. Weak linkages between scaling efforts and enabling policy, institutional, and market frameworks limit impact (Wigboldus, 2018). | L17: Systemic, forward-looking scaling strategies are developed and institutionalized across CGIAR and partner ecosystems. These strategies embed innovation scaling within broader food system transformation pathways, integrate enabling environment analysis, and include flexible, evidence-based scaling pathways. They emphasize sustainability, equity, and adaptive learning to respond to dynamic regional contexts (Gálvez, 2022; CGIAR, 2023; Schut et al., 2024). | M17: High prioritization in SA, ESA, and WCA reflects the recognized need to move beyond piecemeal scaling approaches and institutionalize systemic strategies. It is assumed that while pilot models and successful innovations exist in these regions, their scaling potential remains underutilized due to lack of strategic guidance and system-wide engagement. Cross-initiative coordination and long-term visioning are especially limited (FAO, 2022). | N17: CGIAR must embed scaling strategies as a core design and planning component across all Initiatives, linked to innovation pipelines, MEL systems, and policy engagement. Internal success requires clear accountability for scaling within research teams, the use of scenario-based foresight, and the establishment of cross-Initiative coordination units to harmonize scaling pathways. CGIAR must also invest in internal capacity development for scaling strategy design and systems thinking (Woltering et al., 2019). | O17: Scaling strategies must be co-developed with governments, funders, private sector actors, and civil society to ensure alignment with national food security priorities and development plans. Success requires enabling policy frameworks, long-term financing, and programmatic integration with national delivery systems. Multi-stakeholder governance platforms and regional development actors (e.g., RECs, IFIs) play a critical role in anchoring strategies (World Bank, 2024). | P17: SA, ESA, and WCA are high-priority regions for institutionalizing food system scaling strategies. These regions host numerous fragmented scaling efforts that, if strategically aligned, could drive significant food security gains. Support should focus on scaling diagnostics, co-creation of long-term scaling roadmaps, and embedding these within national food system transformation agendas. Institutionalization of scaling strategy frameworks is essential to achieve coherence and sustained impact in these contexts.
C18: =HLOs!D15 -> HLO 3.3.1: Enabling environment diagnostics | D18: 2 | E18: 2 | F18: 3 | G18: 3 | H18: 3 | I18: 2 | K18: Diagnostics that assess the readiness of policy, institutional, financial, and regulatory environments to support innovation scaling are sparse, sporadic, and often disconnected from program cycles. In many CGIAR programs, barriers to scaling—such as land tenure issues, weak extension systems, or policy misalignment—are acknowledged late or not addressed systematically, resulting in ineffective or unsustainable scaling (World Bank, 2020). | L18: Institutionalized, evidence-based diagnostic frameworks are embedded into the design and implementation of CGIAR and national programs. These diagnostics regularly assess enabling and disabling factors for scaling across institutions, policy regimes, and markets. They are implemented collaboratively with national actors and feed directly into program adaptation, investment planning, and policy dialogue (FAO & WEF, 2022). | M18: SA and SEA received relatively higher priority scores, reflecting urgent gaps in systematic diagnostics to identify institutional and policy bottlenecks. It is assumed that while enabling conditions are often known anecdotally, structured diagnostics—such as political economy analyses or delivery readiness assessments—remain underutilized. WCA also requires strengthening, though data systems and coordination mechanisms are weaker (Gálvez, 2022; CGIAR, 2023; Schut et al., 2024). | N18: Within CGIAR, success requires the mainstreaming of diagnostic tools that assess system readiness across initiatives. These tools must be integrated into programmatic design templates, MEL frameworks, and ex-ante investment appraisal systems. Capacity development is needed across centers to apply political economy, regulatory, and institutional diagnostics, and ensure learning is used to inform scaling strategies (Woltering et al., 2019). | O18: Governments, regional institutions, and donors must commit to using diagnostic evidence to inform food security programming. This includes supporting integrated data systems, incentivizing joint problem analysis across sectors, and aligning diagnostic outputs with national investment planning and reform processes. Platforms for cross-country learning and technical support will help scale diagnostic use (HLPE, 2020). | P18: SA and SEA are priority regions where targeted diagnostic strengthening can improve the strategic focus and coherence of food security investments. These regions require structured tools to identify why certain innovations fail to scale, and to guide reforms in land, extension, subsidy, or institutional frameworks. WCA also merits diagnostic support to overcome governance and coordination barriers. Investments should focus on scaling-relevant diagnostics embedded early in the innovation cycle.
C19: =HLOs!D16 -> HLO 3.3.2: Scaling support services for enabling environments and institutions | D19: 3 | E19: 3 | F19: 3 | G19: 3 | H19: 4 | I19: 3 | K19: Services critical to scaling—such as access to finance, mechanization, technical support, insurance, and digital advisory systems—remain fragmented and uneven across regions. Many CGIAR-aligned innovations are delivered without the ecosystem of services needed for sustained uptake, especially in under-resourced regions. Current efforts often rely on short-term pilots or isolated delivery models, limiting their ability to support wide-scale adoption of food security solutions (FAO, 2022). | L19: A supportive service ecosystem is in place, with bundled offerings—including financial products, capacity development, digital advisory services, and technical assistance—available at scale and aligned with the innovation needs of food-insecure populations. These services are regionally anchored, delivered through public-private partnerships, and designed with inclusivity and affordability in mind (IFPRI, 2023). | M19: Higher regional scores in SA and ESA reflect urgent needs to develop service ecosystems that can enable large-scale deployment of food security innovations. It is assumed that in these regions, fragmented service delivery, limited rural finance penetration, and weak capacity among public extension and private actors continue to constrain scaling. WCA also demonstrates high need, but the ecosystem remains more nascent and resource-constrained (Gálvez, 2022; CGIAR, 2023; Schut et al., 2024). | N19: CGIAR must work across Initiatives to identify critical service bottlenecks tied to innovation adoption. Internal success depends on embedding service gap assessments into scaling diagnostics, piloting bundled support models, and developing tools to monitor service performance. Collaboration between research, scaling, and MELIA teams is essential to co-design scalable service delivery mechanisms adapted to different geographies (Anderson et al., 2020). | O19: CGIAR must partner with public extension, rural finance institutions, agribusinesses, and service provider networks to deliver bundled services that respond to scaling needs. Support is also needed from ministries and donors to build enabling policies (e.g., service delivery subsidies, performance-based contracts) and invest in last-mile infrastructure and service platforms (IFAD, 2019; FAO, 2022). | P19: SA and ESA are high-priority regions for this HLO, where immediate investments in service ecosystems can unlock scaling for food security innovations. WCA also presents opportunities for long-term systems development. Strategic focus should be placed on supporting inclusive, decentralized service delivery models that integrate finance, input access, and advisory tools. These efforts are critical to ensuring adoption beyond early adopters and building sustainable market ecosystems around CGIAR innovations.
