Workbook

Sheet README
A1: Initial prioritization for the Sustainable Farming Program
A2: Method: Follows System Organization Guidance, March 2025
A3: Full methods document: under development
A4: Questions: Todd Rosenstock, t.rosenstock@cgiar.org

Sheet Country-regions
A1: Countries, per region, worked on by [Insert Program/Accelerator name]
A2: CGIAR regions and countries.xlsx | B2: <-- Spreadsheet showing the CGIAR regions and the countries that fall into these regions
A3: Program and Accelerator's Countries (2024).xlsx | B3: <-- Spreadsheet showing the countries that each Program/Accelerator is working on (as per what was submitted in 2024 for the original methodology).
A4: LAC | B4: CWANA | C4: WCA | D4: ESA | E4: SA | F4: SEA
A5: Colmbia | B5: Algeria | C5: Benin | D5: Burundi | E5: Bangladesh | F5: Cambodia
A6: Ecuador | B6: Bahrain | C6: Burkina Faso | D6: Eswatini | E6: India | F6: Laos PDR
A7: Mexico | B7: Egypt | C7: Cameroon | D7: Ethiopia | E7: Nepal | F7: Pilippines
A8: Peru | B8: Iraq | C8: Congo | D8: Kenya | E8: Pakistan | F8: Vietnam
B9: Jordan | C9: Côte d'Ivoire | D9: Lesotho
B10: Kuwait | C10: Democratic Republic of the Congo (DRC) | D10: Madagascar
B11: Lebanon | C11: Ghana | D11: Malawi
B12: Morocco | C12: Liberia | D12: Mozambique
B13: Oman | C13: Mali | D13: Namibia
B14: Palestine | C14: Niger | D14: Rwanda
B15: Qatar | C15: Nigeria | D15: South Africa
B16: Saudi Arabia | C16: Senegal | D16: Sudan
B17: Tunisia | C17: Sierra Leone | D17: Tanzania
B18: Turkey | C18: Togo | D18: Uganda
B19: United Arab Emirates (UAE) | D19: Zambia

Sheet HLOs
A2: VH | B2: 5
A3: H | B3: 4
A4: MH | B4: 3
A5: M | B5: 2
A6: L | B6: 1
C7: # | D7: HLO + concise description
A8: HLO count: | B8: =COUNTA(D8:D58) -> 34 | C8: 1 | D8: HLO 1.1: Quantified climate change-related hazards that affect the delivery of agronomic gain
A9: Sets of 5: | B9: =_xlfn.FLOOR.MATH(B8/5) -> 6 | C9: 2 | D9: HLO 1.2: Climate hazard-specific inclusive sustainable farming system innovations
A10: Remainder: | B10: =MOD(B8,5) -> 4 | C10: 3 | D10: HLO 1.3: Training materials for climate adaptation and mitigation
A11: Max score: | B11: =(B9*SUM($B$2:$B$6))+IF(B8=0,0,SUM(B2:INDEX(B:B,$B$10+1))) -> 104 | C11: 4 | D11: HLO 1.4: Policy and investment-ready information on sustainable farming solutions
C12: 5 | D12: HLO 2.1: Spatially-explicit recommendation decision support models for soil nutrient constraints
C13: 6 | D13: HLO 2.2: Expanded data-driven agronomic recommendations for site-specific nutrient management
C14: 7 | D14: HLO 2.3: Training materials for site-specific nutrient management
C15: 8 | D15: HLO 2.4: Evidence for policy recommendations for precision nutrient management
C16: 9 | D16: HLO 3.1: Soil health monitoring and assessment framework operationalized
C17: 10 | D17: HLO 3.2: Network of long-term monitoring sites for carbon storage assessment
C18: 11 | D18: HLO 3.3: Impacts of agricultural practices quantified and catalogued
C19: 12 | D19: HLO 3.4: Evidence for policy makers on soil health translated to accessible formats
C20: 13 | D20: HLO 4.1: Capacity and networks of plant health practitioners improved
C21: 14 | D21: HLO 4.2: Improved pest and disease monitoring and modeling tools
C22: 15 | D22: HLO 4.3: Surveillance data and prevention strategies available
C23: 16 | D23: HLO 4.4: Eco-friendly options for integrated pest management developed
... C41: 34 | D41: HLO 8.5: Policy-related information for sustainable farming systems
C42: 35
C43: 36
C44: 37
C45: 38
C46: 39
C47: 40
C48: 41
C49: 42
C50: 43
C51: 44
C52: 45
C53: 46
... C57: 50

Sheet Indicators
A1: BASE Indicator database - (from 2024).xlsx | C1: <-- source of Baseline data
A2: Projected Benefits Data (Nov 2024) - With Analysis.xlsx | C2: <-- source of Projected data (with graphs)
A3: Impact Area | B3: Projected to 2040 (without CGIAR intervention) or baseline data? | C3: Indicator | D3: r_lac | E3: r_cwana | F3: r_wca | G3: r_esa | H3: r_sa | I3: r_sea
A5: Nutrition | B5: Baseline data | C5: Prevalence of stunting (height for age <-2 standard deviation from the median of the World Health Organization (WHO) Child Growth Standards) % children under 5 years of age | D5: 11.679145 | E5: 17.238147 | F5: 31.597628 | G5: 30.494793 | H5: 34.286344 | I5: 11.083749
A6: Nutrition | B6: Baseline data | C6: Prevalence of wasting (weight for height >+2 or <-2 standard deviation from the median of the WHO Child Growth Standards) % children under 5 years of age | D6: 2.2309085 | E6: 5.8629686 | F6: 6.7930741 | G6: 5.4676809 | H6: 16.318465 | I6: 3.6836782
A7: Nutrition | B7: Baseline data | C7: % of population unable to afford a healthy diet | D7: 22.261332 | E7: 37.375529 | F7: 84.372957 | G7: 82.105349 | H7: 73.246664 | I7: 24.396071
A8: Nutrition | B8: Baseline data | C8: Women meeting minimum dietary diversity (MDD-W)(%) | D8: 77.386889 | E8: 73.431162 | F8: 47.825418 | G8: 47.455003 | H8: 44.789895 | I8: 84.612374 | J8: MDD-W - higher value indicates more women meeting the minimum (i.e., a lower potential for impact) --- Minimum Dietary Diversity for Women is a population-level food group-based indicator that captures dietary diversity, a core construct of healthy diets. MDD-W is used to estimate the proportion of non-pregnant women aged 15-49 years who consumed at least five out of ten defined food groups over the previous 24 hours, signalling better micronutrient intake. indicator that captures dietary diversity, a core construct of healthy diets. MDD-W is used to estimate the proportion of non-pregnant women aged 15-49 years who consumed at least five out of ten defined food groups over the previous 24 hours, signalling better micronutrient intake. -- Note that we calculated it as 100% minus the MDD-W (i.e., women not meeting ...) such that higher values correspond with higher potential for impact,
A9: Gender | B9: Baseline data | C9: Proportion of youth (aged 15-24 years) not in education, employment or training (NEET) (%) | D9: 20.353948 | E9: 28.808683 | F9: 22.22403 | G9: 22.032946 | H9: 25.579269 | I9: 13.900333
A10: Gender | B10: Baseline data | C10: Gender Development Index (GDI) | D10: 0.98711807 | E10: 0.86109472 | F10: 0.88128823 | G10: 0.92987576 | H10: 0.85713094 | I10: 0.96249076 | J10: GDI measures gender inequalities in achievement in three basic dimensions of human development: health, measured by female and male life expectancy at birth; education, measured by female and male expected years of schooling for children and female and male mean years of schooling for adults ages 25 years and older; and command over economic resources, measured by female and male estimated earned income.
A11: Gender | B11: Baseline data | C11: Gender Inequality Index (GII) | D11: 0.3786 | E11: 0.4202 | F11: 0.6154 | G11: 0.51 | H11: 0.4542 | I11: 0.2426 | J11: GII is a composite metric of gender inequality using three dimensions: reproductive health, empowerment and the labour market. A low GII value indicates low inequality between women and men, and vice-versa.
A12: Poverty | B12: Baseline data | C12: The ratio of the people employed in agriculture in rural areas over all people employed in rural areas" | D12: 46.830763 | E12: 34.609244 | F12: 64.335138 | G12: 71.949092 | H12: 56.611142 | I12: 44.992877
A13: Climate | B13: Baseline data | C13: Vulnerability index of the geography (exposure, sensitivity and adaptive capacity in six life-supporting sectors: food, water, health, ecosystem services, human habitat, and infrastructure). | D13: 0.38522854 | E13: 0.41856096 | F13: 0.52689312 | G13: 0.51707456 | H13: 0.50168331 | I13: 0.40802057
A14: Climate | B14: Baseline data | C14: Emissions intensity - CO2eq emissions from croplands (kg/ha) (Carlson et al., 2017) | D14: 386 | E14: 444 | F14: 312 | G14: 531 | H14: 2090 | I14: 3326
A15: Climate | B15: Baseline data | C15: CRI - Climate Risk Index - the index of the level of exposure and vulnerability to extreme events such as storms, floods and heatwaves based on historic data | D15: 46.593083 | E15: 71.63158 | F15: 73.530172 | G15: 45.434032 | H15: 18.194338 | I15: 40.16028
A16: Environment | B16: Baseline data | C16: Consumptive blue and green water used in food production (m3/ha) | D16: 5008.9819 | E16: 3795.1862 | F16: 4064.7898 | G16: 4368.5844 | H16: 5065.8423 | I16: 6113.5583
A17: Environment | B17: Baseline data | C17: Soil erosion rate (/Ha) | D17: 4480.2558 | E17: 2629.3874 | F17: 5858.9939 | G17: 7924.0507 | H17: 10121.16 | I17: 7076.2489
A18: Environment | B18: Baseline data | C18: Forest area lost (%) - the percentage of forested area (%) lost between 2010 and 2020 | D18: 4.0133292 | E18: 3.0328342 | F18: 8.736605 | G18: 6.4758874 | H18: 0.80036497 | I18: 1.9236632
A19: Environment | B19: Baseline data | C19: GBI - Global Biodiversity Index - Total number of plant, reptile, mammal, bird, fish and amphibian species | D19: 362.31193 | E19: 80.081948 | F19: 116.18798 | G19: 156.28684 | H19: 264.30093 | I19: 324.04395
A20: Environment | B20: Baseline data | C20: Sustainable agriculture score - Index quantifying progress toward productive and sustainable agriculture (current status score) | D20: 3.7142926 | E20: 3.0915505 | F20: 3.2533234 | G20: 2.8150793 | H20: 2.5514288 | I20: 3.9867322
A22: Impact Area | B22: Projected to 2040 (without CGIAR intervention) | C22: Indicator | D22: r_lac | X22: r_cwana | AR22: r_wca | BL22: r_esa | CF22: r_sa | CZ22: r_sea
D23: 2021 | E23: 2022 | F23: 2023 | G23: 2024 | H23: 2025 | I23: 2026 | J23: 2027 | K23: 2028 | L23: 2029 | M23: 2030 | N23: 2031 | O23: 2032 | P23: 2033 | Q23: 2034 | R23: 2035 | S23: 2036 | T23: 2037 | U23: 2038 | V23: 2039 | W23: 2040 | X23: 2021 | Y23: 2022 | Z23: 2023 | AA23: 2024 | AB23: 2025 | AC23: 2026 | AD23: 2027 | AE23: 2028 | AF23: 2029 | AG23: 2030 | AH23: 2031 | AI23: 2032 | AJ23: 2033 | AK23: 2034 | AL23: 2035 | AM23: 2036 | AN23: 2037 | AO23: 2038 | AP23: 2039 | AQ23: 2040 | AR23: 2021 | AS23: 2022 | AT23: 2023 | AU23: 2024 | AV23: 2025 | AW23: 2026 | AX23: 2027 | AY23: 2028 | AZ23: 2029 | BA23: 2030 | BB23: 2031 | BC23: 2032 | BD23: 2033 | BE23: 2034 | BF23: 2035 | BG23: 2036 | BH23: 2037 | BI23: 2038 | BJ23: 2039 | BK23: 2040 | BL23: 2021 | BM23: 2022 | BN23: 2023 | BO23: 2024 | BP23: 2025 | BQ23: 2026 | BR23: 2027 | BS23: 2028 | BT23: 2029 | BU23: 2030 | BV23: 2031 | BW23: 2032 | BX23: 2033 | BY23: 2034 | BZ23: 2035 | CA23: 2036 | CB23: 2037 | CC23: 2038 | CD23: 2039 | CE23: 2040 | CF23: 2021 | CG23: 2022 | CH23: 2023 | CI23: 2024 | CJ23: 2025 | CK23: 2026 | CL23: 2027 | CM23: 2028 | CN23: 2029 | CO23: 2030 | CP23: 2031 | CQ23: 2032 | CR23: 2033 | CS23: 2034 | CT23: 2035 | CU23: 2036 | CV23: 2037 | CW23: 2038 | CX23: 2039 | CY23: 2040 | CZ23: 2021 | DA23: 2022 | DB23: 2023 | DC23: 2024 | DD23: 2025 | DE23: 2026 | DF23: 2027 | DG23: 2028 | DH23: 2029 | DI23: 2030 | DJ23: 2031 | DK23: 2032 | DL23: 2033 | DM23: 2034 | DN23: 2035 | DO23: 2036 | DP23: 2037 | DQ23: 2038 | DR23: 2039 | DS23: 2040
A24: Nutrition | B24: Projected to 2040 | C24: Prevalence of Undernourishment - Share of total population living below the minimum calorie daily threshold | D24: 7.1892578 | E24: 6.68889 | F24: 6.2115266 | G24: 5.7570393 | H24: 5.3252329 | I24: 4.9158466 | J24: 4.5285569 | K24: 4.1629803 | L24: 3.8186764 | M24: 3.4951517 | N24: 3.1918631 | O24: 2.908223 | P24: 2.6436027 | Q24: 2.3973382 | R24: 2.1687341 | S24: 1.9570691 | T24: 1.7616009 | U24: 1.5815713 | V24: 1.4162109 | W24: 1.2647443 | X24: 9.1504665 | Y24: 8.9091662 | Z24: 8.6634743 | AA24: 8.4138444 | AB24: 8.160744 | AC24: 7.9046538 | AD24: 7.6460667 | AE24: 7.3854859 | AF24: 7.123424 | AG24: 6.8604013 | AH24: 6.5969443 | AI24: 6.3335834 | AJ24: 6.0708516 | AK24: 5.809282 | AL24: 5.5494058 | AM24: 5.2917502 | AN24: 5.0368357 | AO24: 4.7851739 | AP24: 4.537265 | AQ24: 4.2935953 | AR24: 18.91209 | AS24: 18.415278 | AT24: 17.911492 | AU24: 17.401678 | AV24: 16.886799 | AW24: 16.367828 | AX24: 15.845748 | AY24: 15.321548 | AZ24: 14.796218 | BA24: 14.270749 | BB24: 13.746128 | BC24: 13.223332 | BD24: 12.703327 | BE24: 12.187064 | BF24: 11.675475 | BG24: 11.169467 | BH24: 10.669921 | BI24: 10.177686 | BJ24: 9.6935781 | BK24: 9.2183741 | BL24: 22.510157 | BM24: 21.490211 | BN24: 20.474437 | BO24: 19.465188 | BP24: 18.464847 | BQ24: 17.475809 | BR24: 16.500465 | BS24: 15.541184 | BT24: 14.600291 | BU24: 13.680052 | BV24: 12.782652 | BW24: 11.910171 | BX24: 11.064571 | BY24: 10.247669 | BZ24: 9.4611245 | CA24: 8.7064163 | CB24: 7.9848318 | CC24: 7.2974499 | CD24: 6.645131 | CE24: 6.0285075 | CF24: 15.036352 | CG24: 13.50078 | CH24: 12.058387 | CI24: 10.711231 | CJ24: 9.460449 | CK24: 8.306251 | CL24: 7.2479364 | CM24: 6.2839238 | CN24: 5.4118015 | CO24: 4.6283937 | CP24: 3.9298411 | CQ24: 3.3116949 | CR24: 2.76902 | CS24: 2.2965049 | CT24: 1.8885759 | CU24: 1.53951 | CV24: 1.2435457 | CW24: 0.99498599 | CX24: 0.78829295 | CY24: 0.6181697 | CZ24: 2.9870488 | DA24: 2.5739841 | DB24: 2.2066181 | DC24: 1.8817105 | DD24: 1.5959854 | DE24: 1.3461739 | DF24: 1.1290543 | DG24: 0.94148797 | DH24: 0.78045059 | DI24: 0.64305899 | DJ24: 0.52659245 | DK24: 0.42850921 | DL24: 0.34645781 | DM24: 0.27828373 | DN24: 0.2220316 | DO24: 0.1759435 | DP24: 0.13845375 | DQ24: 0.10818092 | DR24: 0.083917403 | DS24: 0.06461742
A25: Gender | B25: WE CURRENTLY DON’T HAVE APPROPRIATE INDICATORS PROJECTED FOR THE GENDER IMPACT AREA - PLEASE USE BASELINE DATA ONLY
A26: Poverty | B26: Projected to 2040 | C26: Poverty Headcount Rate ($2.15) - Share of total population living below the poverty line | D26: 4.98557 | E26: 5.0242558 | F26: 5.0621172 | G26: 5.0991222 | H26: 5.1352386 | I26: 5.1704341 | J26: 5.2046757 | K26: 5.2379303 | L26: 5.2701643 | M26: 5.3013441 | N26: 5.3314354 | O26: 5.3604039 | P26: 5.3882149 | Q26: 5.4148334 | R26: 5.4402242 | S26: 5.4643519 | T26: 5.4871807 | U26: 5.5086747 | V26: 5.5287977 | W26: 5.5475134 | X26: 4.59918 | Y26: 4.4042124 | Z26: 4.2131091 | AA26: 4.02598 | AB26: 3.84293 | AC26: 3.6640582 | AD26: 3.4894579 | AE26: 3.319216 | AF26: 3.1534129 | AG26: 2.9921218 | AH26: 2.8354089 | AI26: 2.6833326 | AJ26: 2.5359435 | AK26: 2.3932841 | AL26: 2.2553884 | AM26: 2.1222821 | AN26: 1.9939817 | AO26: 1.8704952 | AP26: 1.7518213 | AQ26: 1.6379496 | AR26: 36.30807 | AS26: 36.185862 | AT26: 36.061701 | AU26: 35.935577 | AV26: 35.807479 | AW26: 35.677395 | AX26: 35.545315 | AY26: 35.411226 | AZ26: 35.275116 | BA26: 35.136975 | BB26: 34.996788 | BC26: 34.854543 | BD26: 34.710229 | BE26: 34.56383 | BF26: 34.415335 | BG26: 34.26473 | BH26: 34.112002 | BI26: 33.957135 | BJ26: 33.800117 | BK26: 33.640934 | BL26: 38.89568 | BM26: 38.85434 | BN26: 38.811608 | BO26: 38.767445 | BP26: 38.721807 | BQ26: 38.674652 | BR26: 38.625933 | BS26: 38.575602 | BT26: 38.523611 | BU26: 38.469907 | BV26: 38.414438 | BW26: 38.357148 | BX26: 38.297978 | BY26: 38.236869 | BZ26: 38.173758 | CA26: 38.10858 | CB26: 38.041268 | CC26: 37.97175 | CD26: 37.899953 | CE26: 37.825801 | CF26: 11.48274 | CG26: 10.469358 | CH26: 9.4825203 | CI26: 8.5274757 | CJ26: 7.6094386 | CK26: 6.7334754 | CL26: 5.904376 | CM26: 5.126516 | CN26: 4.4037126 | CO26: 3.7390816 | CP26: 3.134903 | CQ26: 2.5925037 | CR26: 2.1121683 | CS26: 1.6930861 | CT26: 1.3333448 | CU26: 1.0299761 | CV26: 0.77905634 | CW26: 0.57586239 | CX26: 0.41507324 | CY26: 0.29100712 | CZ26: 1.23059 | DA26: 0.88984793 | DB26: 0.6221891 | DC26: 0.41911725 | DD26: 0.27092336 | DE26: 0.16738356 | DF26: 0.098482932 | DG26: 0.055066945 | DH26: 0.029330068 | DI26: 0.015081471 | DJ26: 0.0077742847 | DK26: 0.0043346014 | DL26: 0.0028635352 | DM26: 0.0022984445 | DN26: 0.0021059525 | DO26: 0.0020486343 | DP26: 0.0020339519 | DQ26: 0.002030774 | DR26: 0.0020302043 | DS26: 0.0020301216
A27: Poverty | B27: Projected to 2040 | C27: Poverty Headcount Rate ($3.65) - Share of total population living below the poverty line | D27: 12.326178 | E27: 12.381889 | F27: 12.436252 | G27: 12.489232 | H27: 12.540798 | I27: 12.590913 | J27: 12.639544 | K27: 12.686654 | L27: 12.732209 | M27: 12.776171 | N27: 12.818504 | O27: 12.85917 | P27: 12.898132 | Q27: 12.935351 | R27: 12.970787 | S27: 13.004401 | T27: 13.036154 | U27: 13.066003 | V27: 13.093907 | W27: 13.119826 | X27: 14.288423 | Y27: 13.982703 | Z27: 13.67684 | AA27: 13.370967 | AB27: 13.065221 | AC27: 12.759739 | AD27: 12.454666 | AE27: 12.150146 | AF27: 11.846328 | AG27: 11.543362 | AH27: 11.241404 | AI27: 10.940608 | AJ27: 10.641135 | AK27: 10.343146 | AL27: 10.046804 | AM27: 9.7522739 | AN27: 9.4597232 | AO27: 9.1693202 | AP27: 8.8812344 | AQ27: 8.5956364 | AR27: 64.127509 | AS27: 64.124548 | AT27: 64.121536 | AU27: 64.118473 | AV27: 64.115359 | AW27: 64.112192 | AX27: 64.108972 | AY27: 64.105699 | AZ27: 64.102372 | BA27: 64.098991 | BB27: 64.095554 | BC27: 64.092063 | BD27: 64.088515 | BE27: 64.08491 | BF27: 64.081248 | BG27: 64.077527 | BH27: 64.073748 | BI27: 64.06991 | BJ27: 64.066011 | BK27: 64.062051 | BL27: 65.516569 | BM27: 65.515305 | BN27: 65.513998 | BO27: 65.512647 | BP27: 65.511251 | BQ27: 65.509807 | BR27: 65.508315 | BS27: 65.506774 | BT27: 65.50518 | BU27: 65.503534 | BV27: 65.501833 | BW27: 65.500075 | BX27: 65.498258 | BY27: 65.496382 | BZ27: 65.494442 | CA27: 65.492439 | CB27: 65.490368 | CC27: 65.488229 | CD27: 65.486018 | CE27: 65.483733 | CF27: 43.13417 | CG27: 42.785936 | CH27: 42.423103 | CI27: 42.045096 | CJ27: 41.651323 | CK27: 41.241181 | CL27: 40.814053 | CM27: 40.369309 | CN27: 39.906311 | CO27: 39.424414 | CP27: 38.922966 | CQ27: 38.401314 | CR27: 37.858808 | CS27: 37.294802 | CT27: 36.708661 | CU27: 36.099766 | CV27: 35.467522 | CW27: 34.811364 | CX27: 34.130765 | CY27: 33.425246 | CZ27: 6.6233529 | DA27: 5.5934126 | DB27: 4.6450586 | DC27: 3.7861739 | DD27: 3.0226307 | DE27: 2.3578335 | DF27: 1.7923687 | DG27: 1.323821 | DH27: 0.94680861 | DI27: 0.65326964 | DJ27: 0.43300161 | DK27: 0.2744137 | DL27: 0.16540941 | DM27: 0.094283044 | DN27: 0.050501138 | DO27: 0.025256507 | DP27: 0.011729008 | DQ27: 0.0050518673 | DR27: 0.0020459537 | DS27: 0.00082542745
A28: Poverty | B28: Projected to 2040 | C28: Poverty Headcount Rate ($6.85) - Share of total population living below the poverty line | D28: 31.99797 | E28: 32.039063 | F28: 32.079058 | G28: 32.117939 | H28: 32.155689 | I28: 32.192292 | J28: 32.227729 | K28: 32.261984 | L28: 32.295038 | M28: 32.326872 | N28: 32.357466 | O28: 32.386801 | P28: 32.414856 | Q28: 32.441611 | R28: 32.467043 | S28: 32.491131 | T28: 32.513851 | U28: 32.535181 | V28: 32.555096 | W28: 32.573571 | X28: 39.779017 | Y28: 39.643681 | Z28: 39.506381 | AA28: 39.367094 | AB28: 39.225797 | AC28: 39.082466 | AD28: 38.937077 | AE28: 38.789605 | AF28: 38.640025 | AG28: 38.488313 | AH28: 38.334443 | AI28: 38.178388 | AJ28: 38.020124 | AK28: 37.859624 | AL28: 37.69686 | AM28: 37.531806 | AN28: 37.364435 | AO28: 37.194718 | AP28: 37.022628 | AQ28: 36.848136 | AR28: 88.509867 | AS28: 88.506906 | AT28: 88.503894 | AU28: 88.500831 | AV28: 88.497716 | AW28: 88.494549 | AX28: 88.49133 | AY28: 88.488056 | AZ28: 88.48473 | BA28: 88.481348 | BB28: 88.477912 | BC28: 88.47442 | BD28: 88.470872 | BE28: 88.467267 | BF28: 88.463605 | BG28: 88.459885 | BH28: 88.456106 | BI28: 88.452267 | BJ28: 88.448368 | BK28: 88.444408 | BL28: 87.43947 | BM28: 87.438206 | BN28: 87.4369 | BO28: 87.435549 | BP28: 87.434152 | BQ28: 87.432709 | BR28: 87.431217 | BS28: 87.429675 | BT28: 87.428082 | BU28: 87.426435 | BV28: 87.424734 | BW28: 87.422976 | BX28: 87.42116 | BY28: 87.419283 | BZ28: 87.417344 | CA28: 87.41534 | CB28: 87.413269 | CC28: 87.41113 | CD28: 87.408919 | CE28: 87.406634 | CF28: 80.974435 | CG28: 80.959243 | CH28: 80.943388 | CI28: 80.92684 | CJ28: 80.909568 | CK28: 80.891539 | CL28: 80.872719 | CM28: 80.853071 | CN28: 80.832558 | CO28: 80.811141 | CP28: 80.788779 | CQ28: 80.765429 | CR28: 80.741045 | CS28: 80.71558 | CT28: 80.688986 | CU28: 80.66121 | CV28: 80.632198 | CW28: 80.601895 | CX28: 80.57024 | CY28: 80.537172 | CZ28: 29.55282 | DA28: 28.453081 | DB28: 27.310321 | DC28: 26.125513 | DD28: 24.900204 | DE28: 23.636605 | DF28: 22.337679 | DG28: 21.007236 | DH28: 19.650019 | DI28: 18.271781 | DJ28: 16.879345 | DK28: 15.480643 | DL28: 14.084712 | DM28: 12.701646 | DN28: 11.342485 | DO28: 10.019034 | DP28: 8.7435908 | DQ28: 7.528593 | DR28: 6.3861649 | DS28: 5.327589
A29: Poverty | B29: Projected to 2040 | C29: Agrifood System Jobs (incl. subsistence farming and informal sector) - millions of workers | D29: 79.453806 | E29: 81.086566 | F29: 82.7612 | G29: 84.478933 | H29: 86.241033 | I29: 88.048807 | J29: 89.903606 | K29: 91.806824 | L29: 93.759905 | M29: 95.764336 | N29: 97.821657 | O29: 99.933458 | P29: 102.10138 | Q29: 104.32713 | R29: 106.61247 | S29: 108.95919 | T29: 111.3692 | U29: 113.84443 | V29: 116.3869 | W29: 118.99868 | X29: 50.377779 | Y29: 51.475884 | Z29: 52.606947 | AA29: 53.772164 | AB29: 54.972781 | AC29: 56.210098 | AD29: 57.485472 | AE29: 58.800317 | AF29: 60.156109 | AG29: 61.554391 | AH29: 62.996771 | AI29: 64.48493 | AJ29: 66.020625 | AK29: 67.605691 | AL29: 69.242045 | AM29: 70.931693 | AN29: 72.676732 | AO29: 74.479356 | AP29: 76.341859 | AQ29: 78.266643 | AR29: 118.18601 | AS29: 122.23843 | AT29: 126.45317 | AU29: 130.8372 | AV29: 135.39785 | AW29: 140.14274 | AX29: 145.07984 | AY29: 150.21751 | AZ29: 155.56444 | BA29: 161.12976 | BB29: 166.92299 | BC29: 172.9541 | BD29: 179.23348 | BE29: 185.77203 | BF29: 192.58113 | BG29: 199.67268 | BH29: 207.05915 | BI29: 214.75354 | BJ29: 222.76947 | BK29: 231.1212 | BL29: 152.33566 | BM29: 158.07421 | BN29: 164.07237 | BO29: 170.34342 | BP29: 176.90137 | BQ29: 183.76104 | BR29: 190.93808 | BS29: 198.44902 | BT29: 206.31135 | BU29: 214.54355 | BV29: 223.16518 | BW29: 232.19692 | BX29: 241.66066 | BY29: 251.57954 | BZ29: 261.9781 | CA29: 272.88229 | CB29: 284.3196 | CC29: 296.31915 | CD29: 308.91182 | CE29: 322.1303 | CF29: 335.11902 | CG29: 345.66882 | CH29: 356.63814 | CI29: 368.04754 | CJ29: 379.91877 | CK29: 392.27487 | CL29: 405.14024 | CM29: 418.54076 | CN29: 432.50383 | CO29: 447.05854 | CP29: 462.23575 | CQ29: 478.06821 | CR29: 494.5907 | CS29: 511.84016 | CT29: 529.85585 | CU29: 548.6795 | CV29: 568.3555 | CW29: 588.93105 | CX29: 610.45641 | CY29: 632.98506 | CZ29: 430.51747 | DA29: 439.33041 | DB29: 448.38064 | DC29: 457.67536 | DD29: 467.22202 | DE29: 477.02828 | DF29: 487.10209 | DG29: 497.45165 | DH29: 508.08544 | DI29: 519.0122 | DJ29: 530.24097 | DK29: 541.7811 | DL29: 553.64225 | DM29: 565.8344 | DN29: 578.36786 | DO29: 591.25328 | DP29: 604.5017 | DQ29: 618.12449 | DR29: 632.13342 | DS29: 646.54069
A30: Poverty | B30: Projected to 2040 | C30: Agrifood System GDP Per Worker - US$ per worker | D30: 9757.9382 | E30: 9757.9382 | F30: 9757.9382 | G30: 9757.9382 | H30: 9757.9382 | I30: 9757.9382 | J30: 9757.9382 | K30: 9757.9382 | L30: 9757.9382 | M30: 9757.9382 | N30: 9757.9382 | O30: 9757.9382 | P30: 9757.9382 | Q30: 9757.9382 | R30: 9757.9382 | S30: 9757.9382 | T30: 9757.9382 | U30: 9757.9382 | V30: 9757.9382 | W30: 9757.9382 | X30: 11320.812 | Y30: 11320.812 | Z30: 11320.812 | AA30: 11320.812 | AB30: 11320.812 | AC30: 11320.812 | AD30: 11320.812 | AE30: 11320.812 | AF30: 11320.812 | AG30: 11320.812 | AH30: 11320.812 | AI30: 11320.812 | AJ30: 11320.812 | AK30: 11320.812 | AL30: 11320.812 | AM30: 11320.812 | AN30: 11320.812 | AO30: 11320.812 | AP30: 11320.812 | AQ30: 11320.812 | AR30: 2860.2434 | AS30: 2860.2434 | AT30: 2860.2434 | AU30: 2860.2434 | AV30: 2860.2434 | AW30: 2860.2434 | AX30: 2860.2434 | AY30: 2860.2434 | AZ30: 2860.2434 | BA30: 2860.2434 | BB30: 2860.2434 | BC30: 2860.2434 | BD30: 2860.2434 | BE30: 2860.2434 | BF30: 2860.2434 | BG30: 2860.2434 | BH30: 2860.2434 | BI30: 2860.2434 | BJ30: 2860.2434 | BK30: 2860.2434 | BL30: 1686.5692 | BM30: 1686.5692 | BN30: 1686.5692 | BO30: 1686.5692 | BP30: 1686.5692 | BQ30: 1686.5692 | BR30: 1686.5692 | BS30: 1686.5692 | BT30: 1686.5692 | BU30: 1686.5692 | BV30: 1686.5692 | BW30: 1686.5692 | BX30: 1686.5692 | BY30: 1686.5692 | BZ30: 1686.5692 | CA30: 1686.5692 | CB30: 1686.5692 | CC30: 1686.5692 | CD30: 1686.5692 | CE30: 1686.5692 | CF30: 2772.7337 | CG30: 2772.7337 | CH30: 2772.7337 | CI30: 2772.7337 | CJ30: 2772.7337 | CK30: 2772.7337 | CL30: 2772.7337 | CM30: 2772.7337 | CN30: 2772.7337 | CO30: 2772.7337 | CP30: 2772.7337 | CQ30: 2772.7337 | CR30: 2772.7337 | CS30: 2772.7337 | CT30: 2772.7337 | CU30: 2772.7337 | CV30: 2772.7337 | CW30: 2772.7337 | CX30: 2772.7337 | CY30: 2772.7337 | CZ30: 8556.862 | DA30: 8556.862 | DB30: 8556.862 | DC30: 8556.862 | DD30: 8556.862 | DE30: 8556.862 | DF30: 8556.862 | DG30: 8556.862 | DH30: 8556.862 | DI30: 8556.862 | DJ30: 8556.862 | DK30: 8556.862 | DL30: 8556.862 | DM30: 8556.862 | DN30: 8556.862 | DO30: 8556.862 | DP30: 8556.862 | DQ30: 8556.862 | DR30: 8556.862 | DS30: 8556.862
A31: Climate | B31: Projected to 2040 | C31: Agrifood System Greenhouse Gas (GHG) Emissions | D31: 1290.6349 | E31: 1299.4607 | F31: 1308.4565 | G31: 1317.627 | H31: 1326.977 | I31: 1336.5113 | J31: 1346.2348 | K31: 1356.1529 | L31: 1366.2709 | M31: 1376.5942 | N31: 1387.1287 | O31: 1397.8802 | P31: 1408.8548 | Q31: 1420.0587 | R31: 1431.4986 | S31: 1443.181 | T31: 1455.113 | U31: 1467.3017 | V31: 1479.7545 | W31: 1492.4791 | X31: 521.24598 | Y31: 532.37733 | Z31: 543.82156 | AA31: 555.58869 | AB31: 567.68908 | AC31: 580.13348 | AD31: 592.93304 | AE31: 606.09934 | AF31: 619.64439 | AG31: 633.58065 | AH31: 647.92106 | AI31: 662.67905 | AJ31: 677.86859 | AK31: 693.50417 | AL31: 709.60086 | AM31: 726.17432 | AN31: 743.24082 | AO31: 760.81729 | AP31: 778.92133 | AQ31: 797.57126 | AR31: 420.59141 | AS31: 431.825 | AT31: 443.40263 | AU31: 455.3357 | AV31: 467.63605 | AW31: 480.31594 | AX31: 493.38808 | AY31: 506.86563 | AZ31: 520.76222 | BA31: 535.09201 | BB31: 549.86963 | BC31: 565.11028 | BD31: 580.82972 | BE31: 597.04426 | BF31: 613.77085 | BG31: 631.02704 | BH31: 648.83104 | BI31: 667.20175 | BJ31: 686.15877 | BK31: 705.72241 | BL31: 552.78648 | BM31: 575.08538 | BN31: 598.466 | BO31: 622.98755 | BP31: 648.71274 | BQ31: 675.70795 | BR31: 704.0435 | BS31: 733.79384 | BT31: 765.03783 | BU31: 797.85902 | BV31: 832.34591 | BW31: 868.59228 | BX31: 906.69748 | BY31: 946.76683 | BZ31: 988.91191 | CA31: 1033.251 | CB31: 1079.9095 | CC31: 1129.0204 | CD31: 1180.7245 | CE31: 1235.1714 | CF31: 1337.1419 | CG31: 1368.6614 | CH31: 1401.2786 | CI31: 1435.0419 | CJ31: 1470.0024 | CK31: 1506.2136 | CL31: 1543.732 | CM31: 1582.6166 | CN31: 1622.9297 | CO31: 1664.7367 | CP31: 1708.1063 | CQ31: 1753.1111 | CR31: 1799.8271 | CS31: 1848.3343 | CT31: 1898.7173 | CU31: 1951.0646 | CV31: 2005.4699 | CW31: 2062.0314 | CX31: 2120.8529 | CY31: 2182.0435 | CZ31: 2408.5001 | DA31: 2440.4414 | DB31: 2473.2397 | DC31: 2506.9196 | DD31: 2541.5063 | DE31: 2577.0259 | DF31: 2613.5052 | DG31: 2650.9722 | DH31: 2689.4553 | DI31: 2728.9842 | DJ31: 2769.5894 | DK31: 2811.3024 | DL31: 2854.1556 | DM31: 2898.1827 | DN31: 2943.4182 | DO31: 2989.8979 | DP31: 3037.6588 | DQ31: 3086.7389 | DR31: 3137.1777 | DS31: 3189.0156
A34: Prevalence of Undernourishment
A52: Undernourished Population
A69: Poverty Headcount Rate ($2.15)
A85: Poverty Headcount Rate ($3.65)
A102: Poverty Headcount Rate ($6.85)
A119: Agrifood System Jobs (incl. subsistence farming and informal sector)
A137: Agricultural Jobs (incl. subsistence farming and informal sector)
A154: Agricultural Greenhouse Gas (GHG) Emissions

Sheet 1.Food_security
C1: FS Indicators
A2: VH | B2: 5 | D2: LAC | E2: CWANA | F2: WCA | G2: ESA | H2: SA | I2: SEA
A3: H | B3: 4 | C3: Total score by column | D3: =SUM(D11:D61) -> 104 | E3: =SUM(E11:E61) -> 104 | F3: =SUM(F11:F61) -> 104 | G3: =SUM(G11:G61) -> 104 | H3: =SUM(H11:H61) -> 104 | I3: =SUM(I11:I61) -> 104
A4: MH | B4: 3 | C4: VH count by column | D4: =COUNTIF(D$11:D$61, 5) -> 5 | E4: =COUNTIF(E$11:E$61, 5) -> 7 | F4: =COUNTIF(F$11:F$61, 5) -> 5 | G4: =COUNTIF(G$11:G$61, 5) -> 7 | H4: =COUNTIF(H$11:H$61, 5) -> 4 | I4: =COUNTIF(I$11:I$61, 5) -> 6
A5: M | B5: 2 | C5: H count by column | D5: =COUNTIF(D$11:D$61, 4) -> 10 | E5: =COUNTIF(E$11:E$61, 4) -> 7 | F5: =COUNTIF(F$11:F$61, 4) -> 7 | G5: =COUNTIF(G$11:G$61, 4) -> 8 | H5: =COUNTIF(H$11:H$61, 4) -> 12 | I5: =COUNTIF(I$11:I$61, 4) -> 9
A6: L | B6: 1 | C6: MH count by column | D6: =COUNTIF(D$11:D$61, 3) -> 6 | E6: =COUNTIF(E$11:E$61, 3) -> 5 | F6: =COUNTIF(F$11:F$61, 3) -> 10 | G6: =COUNTIF(G$11:G$61, 3) -> 6 | H6: =COUNTIF(H$11:H$61, 3) -> 4 | I6: =COUNTIF(I$11:I$61, 3) -> 5
C7: M count by column | D7: =COUNTIF(D$11:D$61, 2) -> 8 | E7: =COUNTIF(E$11:E$61, 2) -> 11 | F7: =COUNTIF(F$11:F$61, 2) -> 9 | G7: =COUNTIF(G$11:G$61, 2) -> 6 | H7: =COUNTIF(H$11:H$61, 2) -> 10 | I7: =COUNTIF(I$11:I$61, 2) -> 9
C8: L count by column | D8: =COUNTIF(D$11:D$61, 1) -> 5 | E8: =COUNTIF(E$11:E$61, 1) -> 4 | F8: =COUNTIF(F$11:F$61, 1) -> 3 | G8: =COUNTIF(G$11:G$61, 1) -> 7 | H8: =COUNTIF(H$11:H$61, 1) -> 4 | I8: =COUNTIF(I$11:I$61, 1) -> 5 | K8: Current state (across the Global South) | L8: Ideal state (across the Global South) | M8: Assumptions (for region-specific scores) | N8: Requirements for success (internal to P/A) | O8: Requirements for success (from other P/As)
C10: HLO | D10: LAC | E10: CWANA | F10: WCA | G10: ESA | H10: SA | I10: SEA
A11: HLO count: | B11: =COUNTA(C11:C61) -> 34 | C11: HLO 1.1: Quantified climate change-related hazards that affect the delivery of agronomic gain | D11: 4 | E11: 4 | F11: 3 | G11: 3 | H11: 4 | I11: 4 | K11: Limited understanding of how climate hazards specifically impact food production and nutritional outcomes in vulnerable regions. | L11: Comprehensive mapping of climate-nutrition pathways enabling targeted interventions to protect food security in changing conditions. | M11: Regional variations in climate-nutrition vulnerability, food system resilience, and nutritional baseline status. | N11: Integrated climate-nutrition modeling, food security impact assessments, and nutritional risk mapping. | O11: Collaboration with Nutrition Program for impact pathways; Food Systems Program for systemic integration.
A12: Sets of 5: | B12: =_xlfn.FLOOR.MATH(B11/5) -> 6 | C12: HLO 1.2: Climate hazard-specific inclusive sustainable farming system innovations | D12: 4 | E12: 4 | F12: 3 | G12: 3 | H12: 4 | I12: 4 | K12: Current adaptation practices rarely prioritize nutritional outcomes, focusing primarily on yield maintenance rather than dietary quality. | L12: Climate-adaptive farming systems optimized for nutritional security, dietary diversity, and stable food access across changing conditions. | M12: Regional differences in dietary patterns, nutritional challenges, and climate-sensitive food production systems. | N12: Nutrition-sensitive adaptation research, food system resilience metrics, and dietary outcome monitoring. | O12: Integration with Nutrition Program for diet-sensitive design; Gender Program for household food security impacts.
A13: Remainder: | B13: =MOD(B11,5) -> 4 | C13: HLO 1.3: Training materials for climate adaptation and mitigation | D13: 4 | E13: 2 | F13: 3 | G13: 3 | H13: 4 | I13: 4 | K13: Extension materials rarely integrate nutrition-sensitive adaptation, limiting impact on dietary outcomes under climate stress. | L13: Capacity development resources enabling implementers to optimize both climate resilience and nutritional outcomes across food systems. | M13: Variations in extension capacity, nutrition awareness, and prioritization of dietary outcomes in agricultural training. | N13: Nutrition-sensitive adaptation curricula, dietary impact training modules, and household food security assessment tools. | O13: Partnership with Capacity Sharing Accelerator; Nutrition Program for technical content.
A14: Max score: | B14: =(B12*SUM($B$2:$B$6))+IF(B11=0,0,SUM($B$2:INDEX(B:B,$B$13+1))) -> 104 | C14: HLO 1.4: Policy and investment-ready information on sustainable farming solutions | D14: 4 | E14: 4 | F14: 3 | G14: 2 | H14: 4 | I14: 4 | K14: Climate policy frameworks rarely prioritize nutritional outcomes, missing opportunities to protect dietary quality under changing conditions. | L14: Integrated climate-nutrition policies guiding investments toward farming systems that maintain food security while building resilience. | M14: Differences in policy integration, nutrition prioritization in climate agendas, and food security governance. | N14: Climate-nutrition policy analysis, investment case development for nutrition-sensitive adaptation, and stakeholder engagement. | O14: Collaboration with Policy Program; Nutrition Program for technical framing.
C15: HLO 2.1: Spatially-explicit recommendation decision support models for soil nutrient constraints | D15: 5 | E15: 5 | F15: 3 | G15: 5 | H15: 5 | I15: 5 | K15: Nutrient recommendations are largely blanket and disconnected from localized soil and crop needs, limiting their effectiveness in addressing food insecurity and micronutrient deficiencies. | L15: Spatially-explicit, data-driven nutrient recommendation models are widely adopted and tailored to local agroecological and socio-economic conditions, enabling farmers to optimize yield, improve soil health, and contribute to food and nutrition security. | M15: It is assumed that agroecological diversity, data availability, institutional capacity, and farmer adoption potential vary significantly across regions, influencing impact. | N15: High-resolution, geo-referenced soil and crop data, robust spatial modeling tools, and integration with climate and agronomic datasets are essential for accurate and actionable recommendations. | O15: Strong extension systems, multi-stakeholder engagement, enabling policies, and farmer-centric delivery platforms are critical to ensure adoption and scalability of nutrient management advisories.
C16: HLO 2.2: Expanded data-driven agronomic recommendations for site-specific nutrient management | D16: 5 | E16: 4 | F16: 3 | G16: 5 | H16: 5 | I16: 4 | K16: Agronomic recommendations are often generalized and not data-driven, resulting in suboptimal nutrient use, low productivity, and limited progress toward food and nutrition security goals. | L16: Site-specific, data-driven agronomic recommendation systems are operational at scale, enabling tailored nutrient management that enhances yield, profitability, resource efficiency, and nutritional outcomes. | M16: Assumes variable quality and availability of agronomic, soil, and weather data; differences in digital infrastructure; and diverse levels of institutional support and farmer digital literacy across regions. | N16: Robust decision support tools, integration of multi-source datasets (e.g., soil, crop, climate, socioeconomic), and continuous feedback mechanisms to refine nutrient recommendations. | O16: Collaborative research-extension systems, policy incentives, digital access for smallholders, and inclusive capacity development are essential to scale and sustain adoption of site-specific nutrient management practices.
C17: HLO 2.3: Training materials for site-specific nutrient management | D17: 5 | E17: 2 | F17: 3 | G17: 3 | H17: 5 | I17: 4 | K17: Training materials on nutrient management are often generic, outdated, or disconnected from local conditions, limiting their effectiveness in promoting site-specific and sustainable practices among farmers and extension agents. | L17: Localized, user-friendly, and digitally accessible training materials are widely available and regularly updated, equipping farmers, extension workers, and advisors with practical guidance for implementing site-specific nutrient management. | M17: Assumes varying levels of literacy, digital access, language needs, and agronomic knowledge across regions, affecting how training content is designed, delivered, and absorbed. | N17: Development of modular, multimedia content co-designed with users, based on local data and decision tools, and adaptable to different delivery formats (print, app, video, radio). | O17: Strong partnerships with NARES, NGOs, and private sector actors; capacity building for trainers; and sustained investment in outreach mechanisms that ensure inclusive access and adoption.
C18: HLO 2.4: Evidence for policy recommendations for precision nutrient management | D18: 4 | E18: 4 | F18: 2 | G18: 5 | H18: 4 | I18: 4 | K18: Policy frameworks often lack robust, localized evidence to support precision nutrient management, resulting in limited policy alignment with sustainable intensification and food security goals. | L18: Policies are informed by strong scientific evidence and field-based outcomes, enabling support for precision nutrient management through targeted subsidies, regulatory frameworks, and national extension strategies. | M18: Assumes variation in policy responsiveness, availability of empirical data, institutional coordination, and political will across countries and regions. | N18: Rigorous multi-location field trials, impact assessments, and harmonized data systems that generate credible evidence on productivity, economic returns, and environmental outcomes. | O18: Close collaboration with policymakers, think tanks, and national research systems; strategic communication of evidence; and alignment with broader agricultural, environmental, and nutrition policy agendas.
C19: HLO 3.1: Soil health monitoring and assessment framework operationalized | D19: 5 | E19: 5 | F19: 2 | G19: 2 | H19: 4 | I19: 5 | K19: Soil health monitoring rarely includes indicators relevant to nutritional security or dietary quality outcomes. | L19: Comprehensive soil monitoring systems tracking both agricultural productivity and nutritional quality determinants. | M19: Regional differences in soil monitoring capacity, nutrition-soil linkage awareness, and monitoring priorities. | N19: Nutrition-relevant soil indicator development, integrated monitoring system design, and outcome tracking methodologies. | O19: Collaboration with Digital Accelerator for systems; Nutrition Program for indicator framework.
C20: HLO 3.2: Network of long-term monitoring sites for carbon storage assessment | D20: 4 | E20: 5 | F20: 2 | G20: 2 | H20: 2 | I20: 4 | K20: Long-term agricultural monitoring rarely tracks nutritional outcomes alongside environmental parameters. | L20: Monitoring networks documenting interactions between soil health, environmental parameters, and nutritional outcomes over time. | M20: Variations in research infrastructure, nutrition-environment research traditions, and monitoring priorities. | N20: Nutrition-sensitive monitoring design, long-term experimental protocols, and integrated outcome assessment methodologies. | O20: Partnership with Environmental Health Program; Nutrition Program for dietary indicators.
C21: HLO 3.3: Impacts of agricultural practices quantified and catalogued | D21: 4 | E21: 2 | F21: 2 | G21: 2 | H21: 2 | I21: 2 | K21: Limited evidence on how soil management practices impact nutritional outcomes hinders nutrition-sensitive agriculture. | L21: Comprehensive evidence base linking soil management practices to both productivity and nutritional outcomes across contexts. | M21: Regional differences in research coverage, nutrition-soil linkage understanding, and evidence synthesis capacity. | N21: Nutrition impact assessment methodologies, evidence synthesis protocols, and knowledge management systems. | O21: Integration with Nutrition Program for outcome framework; Digital Accelerator for knowledge systems.
C22: HLO 3.4: Evidence for policy makers on soil health translated to accessible formats | D22: 4 | E22: 2 | F22: 2 | G22: 2 | H22: 2 | I22: 2 | K22: Soil health policy rarely incorporates nutritional considerations, missing critical soil-diet-health connections. | L22: Soil policies explicitly addressing nutritional security through maintenance of nutrient-supporting soil functions. | M22: Differences in policy environments, nutrition-soil linkage awareness, and policy integration capacity. | N22: Nutrition-soil policy analysis, evidence translation methodologies, and stakeholder engagement strategies. | O22: Partnership with Policy Program; Nutrition Program for framing and messaging.
C23: HLO 4.1: Capacity and networks of plant health practitioners improved | D23: 2 | E23: 2 | F23: 2 | G23: 2 | H23: 2 | I23: 4 | K23: Plant health systems rarely prioritize nutrition-sensitive crop protection, focusing primarily on yield protection. | L23: Practitioner networks optimizing plant health management for both yield stability and nutritional quality maintenance. | M23: Regional variations in plant health system capacity, nutrition awareness, and crop protection priorities. | N23: Nutrition-sensitive plant health training, network development methodologies, and integrated impact assessment tools. | O23: Collaboration with Capacity Sharing Accelerator; Nutrition Program for dietary quality parameters.
C24: HLO 4.2: Improved pest and disease monitoring and modeling tools | D24: 3 | E24: 3 | F24: 3 | G24: 3 | H24: 3 | I24: 3 | K24: Pest monitoring systems rarely consider nutritional consequences, potentially sacrificing dietary quality for yield protection. | L24: Advanced surveillance systems protecting both yield and nutritional quality through targeted monitoring of nutrition-critical crops. | M24: Differences in monitoring infrastructure, nutrition-pest impact understanding, and surveillance priorities. | N24: Nutrition-sensitive pest monitoring design, impact modeling methodologies, and outcome tracking protocols. | O24: Partnership with Digital Accelerator for systems; Nutrition Program for crop prioritization.
C25: HLO 4.3: Surveillance data and prevention strategies available | D25: 3 | E25: 2 | F25: 4 | G25: 4 | H25: 2 | I25: 3 | K25: Prevention strategies rarely differentiate nutritional importance of crops, potentially underprotecting dietary diversity contributors. | L25: Evidence-based prevention strategies prioritizing nutritionally important crops and protecting dietary quality. | M25: Regional variations in prevention capacity, nutrition-pest relationship awareness, and strategic priorities. | N25: Nutrition-sensitive prioritization frameworks, prevention strategy design methodologies, and impact assessment tools. | O25: Integration with Nutrition Program for dietary importance mapping; Scaling Program for deployment.
C26: HLO 4.4: Eco-friendly options for integrated pest management developed | D26: 4 | E26: 4 | F26: 5 | G26: 5 | H26: 4 | I26: 5 | K26: Ecological management approaches rarely optimize for both environmental and nutritional outcomes simultaneously. | L26: Integrated management systems protecting dietary diversity while maintaining environmental sustainability across farm systems. | M26: Differences in ecological management capacity, nutrition awareness, and implementation priorities. | N26: Nutrition-sensitive IPM design, participatory testing methodologies, and multi-objective assessment tools. | O26: Collaboration with Biodiversity Program for approaches; Nutrition Program for outcome assessment.
... C44: HLO 8.5: Policy-related information for sustainable farming systems | D44: 2 | E44: 2 | F44: 1 | G44: 1 | H44: 2 | I44: 2 | K44: Limited policy coherence between agriculture and nutrition sectors undermines food security outcomes. | L44: Systematic integration of farming systems evidence into nutrition-sensitive agricultural policy across governance scales. | M44: Regional variations in policy-science interfaces, cross-sectoral coordination capacity, and governance approaches. | N44: Nutrition-agriculture policy analysis, evidence synthesis methodologies, and cross-sectoral communication protocols. | O44: Strong integration with Policy Program; Nutrition Program for framing and priorities.

Sheet 2.Poverty_reduction
C1: Poverty Indicators
A2: VH | B2: 5 | D2: LAC | E2: CWANA | F2: WCA | G2: ESA | H2: SA | I2: SEA
A3: H | B3: 4 | C3: total score by column | D3: =SUM(D11:D61) -> 104 | E3: =SUM(E11:E61) -> 104 | F3: =SUM(F11:F61) -> 104 | G3: =SUM(G11:G61) -> 104 | H3: =SUM(H11:H61) -> 104 | I3: =SUM(I11:I61) -> 103
A4: MH | B4: 3 | C4: VH count by column | D4: =COUNTIF(D$11:D$61, 5) -> 6 | E4: =COUNTIF(E$11:E$61, 5) -> 5 | F4: =COUNTIF(F$11:F$61, 5) -> 5 | G4: =COUNTIF(G$11:G$61, 5) -> 7 | H4: =COUNTIF(H$11:H$61, 5) -> 3 | I4: =COUNTIF(I$11:I$61, 5) -> 7
A5: M | B5: 2 | C5: H count by column | D5: =COUNTIF(D$11:D$61, 4) -> 9 | E5: =COUNTIF(E$11:E$61, 4) -> 11 | F5: =COUNTIF(F$11:F$61, 4) -> 9 | G5: =COUNTIF(G$11:G$61, 4) -> 5 | H5: =COUNTIF(H$11:H$61, 4) -> 13 | I5: =COUNTIF(I$11:I$61, 4) -> 7
A6: L | B6: 1 | C6: MH count by column | D6: =COUNTIF(D$11:D$61, 3) -> 5 | E6: =COUNTIF(E$11:E$61, 3) -> 3 | F6: =COUNTIF(F$11:F$61, 3) -> 8 | G6: =COUNTIF(G$11:G$61, 3) -> 10 | H6: =COUNTIF(H$11:H$61, 3) -> 3 | I6: =COUNTIF(I$11:I$61, 3) -> 5
C7: M count by column | D7: =COUNTIF(D$11:D$61, 2) -> 9 | E7: =COUNTIF(E$11:E$61, 2) -> 11 | F7: =COUNTIF(F$11:F$61, 2) -> 7 | G7: =COUNTIF(G$11:G$61, 2) -> 7 | H7: =COUNTIF(H$11:H$61, 2) -> 13 | I7: =COUNTIF(I$11:I$61, 2) -> 10
C8: L count by column | D8: =COUNTIF(D$11:D$61, 1) -> 5 | E8: =COUNTIF(E$11:E$61, 1) -> 4 | F8: =COUNTIF(F$11:F$61, 1) -> 5 | G8: =COUNTIF(G$11:G$61, 1) -> 5 | H8: =COUNTIF(H$11:H$61, 1) -> 2 | I8: =COUNTIF(I$11:I$61, 1) -> 5 | K8: Current state (across the Global South) | L8: Ideal state (across the Global South) | M8: Assumptions (for region-specific scores) | N8: Requirements for success (internal to P/A) | O8: Requirements for success (from other P/As)
C10: HLO | D10: LAC | E10: CWANA | F10: WCA | G10: ESA | H10: SA | I10: SEA
A11: HLO count: | B11: =COUNTA(C11:C61) -> 34 | C11: HLO 1.1: Quantified climate change-related hazards that affect the delivery of agronomic gain | D11: 4 | E11: 4 | F11: 3 | G11: 3 | H11: 4 | I11: 4 | K11: Limited understanding of how climate hazards specifically impact income stability, rural employment, and poverty trajectories. | L11: Comprehensive mapping of climate-livelihood pathways enabling targeted interventions to protect economic wellbeing under changing conditions. | M11: Regional variations in climate-livelihood vulnerability, economic diversification, and poverty baseline status. | N11: Integrated climate-poverty modeling, livelihood impact assessments, and economic vulnerability mapping. | O11: Collaboration with Foresight services for socioeconomic projections; Markets Program for value chain impacts.
A12: Sets of 5: | B12: =_xlfn.FLOOR.MATH(B11/5) -> 6 | C12: HLO 1.2: Climate hazard-specific inclusive sustainable farming system innovations | D12: 4 | E12: 4 | F12: 3 | G12: 3 | H12: 4 | I12: 5 | K12: Adaptation technologies often fail to explicitly consider livelihood impacts, employment effects, or poverty reduction potential. | L12: Climate-adaptive farming systems optimized for stable incomes, job creation, and poverty reduction across changing environmental conditions. | M12: Differences in economic vulnerability, livelihood diversification opportunities, and labor market dynamics across regions. | N12: Income-sensitive adaptation research, employment impact assessment methodologies, and poverty reduction metrics. | O12: Integration with Markets Program for value chain evaluation; Policy Program for enabling environment analysis.
A13: Remainder: | B13: =MOD(B11,5) -> 4 | C13: HLO 1.3: Training materials for climate adaptation and mitigation | D13: 4 | E13: 4 | F13: 3 | G13: 3 | H13: 4 | I13: 4 | K13: Extension materials rarely highlight economic implications, business model adaptation, or livelihood diversification opportunities. | L13: Capacity development resources enabling implementers to optimize economic outcomes alongside environmental resilience in adaptation strategies. | M13: Variations in extension capacity, enterprise development support, and prioritization of economic dimensions in training. | N13: Economic impact training modules, business adaptation curricula, and income diversification assessment tools. | O13: Partnership with Capacity Sharing Accelerator; Markets Program for enterprise content.
A14: Max score: | B14: =(B12*SUM($B$2:$B$6))+IF(B11=0,0,SUM($B$2:INDEX(B:B,$B$13+1))) -> 104 | C14: HLO 1.4: Policy and investment-ready information on sustainable farming solutions | D14: 4 | E14: 4 | F14: 3 | G14: 3 | H14: 4 | I14: 4 | K14: Climate policy frameworks rarely prioritize employment protection, income stability, or poverty reduction potential of interventions. | L14: Integrated climate-economic policies guiding investments toward farming systems that maintain livelihoods while building resilience. | M14: Differences in policy integration, economic prioritization in climate agendas, and poverty reduction governance. | N14: Climate-economic policy analysis, livelihood-focused investment case development, and poverty impact assessment. | O14: Collaboration with Policy Program; Markets Program for value chain frameworks.
C15: HLO 2.1: Spatially-explicit recommendation decision support models for soil nutrient constraints | D15: 5 | E15: 5 | F15: 5 | G15: 3 | H15: 5 | I15: 5 | K15: Nutrient management technologies rarely optimize for economic returns, labor implications, or poverty reduction impact. | L15: Precision nutrient systems enhancing both agricultural productivity and economic returns across diverse socioeconomic contexts. | M15: Regional variations in input markets, labor costs, and poverty-nutrient management relationships. | N15: Economic return modeling capacity, poverty impact assessment methodologies, and livelihood-oriented spatial analysis. | O15: Integration with Digital Accelerator for systems; Markets Program for economic analysis.
C16: HLO 2.2: Expanded data-driven agronomic recommendations for site-specific nutrient management | D16: 5 | E16: 4 | F16: 3 | G16: 3 | H16: 5 | I16: 2 | K16: Advisory services rarely incorporate economic optimization, return-on-investment analysis, or poverty impact considerations. | L16: Integrated nutrient recommendations explicitly balancing agronomic, environmental, and economic outcomes for livelihood enhancement. | M16: Differences in advisory system economic capacity, business model integration, and poverty-sensitive recommendation approaches. | N16: Economic return algorithms, cost-benefit modeling tools, and poverty-sensitive recommendation frameworks. | O16: Collaboration with Markets Program; Digital Accelerator for delivery systems.
C17: HLO 2.3: Training materials for site-specific nutrient management | D17: 5 | E17: 5 | F17: 3 | G17: 3 | H17: 5 | I17: 4 | K17: Extension resources rarely emphasize business case development, economic analysis, or livelihood enhancement strategies. | L17: Capacity building materials enabling practitioners to optimize nutrient management for economic returns and poverty reduction. | M17: Regional differences in business extension capacity, economic training infrastructure, and poverty-focused advisory services. | N17: Economic analysis training curricula, business case development tools, and poverty-sensitive advisory methodologies. | O17: Partnership with Capacity Sharing Accelerator; Markets Program for business content.
C18: HLO 2.4: Evidence for policy recommendations for precision nutrient management | D18: 4 | E18: 4 | F18: 2 | G18: 2 | H18: 2 | I18: 2 | K18: Policy frameworks rarely optimize fertilizer programs for income generation, job creation, or poverty reduction outcomes. | L18: Evidence-based policies balancing productivity, sustainability, and economic returns from nutrient management investments. | M18: Variations in policy environments, subsidy economic efficiency, and poverty-reduction focus in input systems. | N18: Economic policy analysis, poverty impact evidence synthesis, and subsidy optimization methodologies. | O18: Strong integration with Policy Program; Markets Program for value chain analysis.
C19: HLO 3.1: Soil health monitoring and assessment framework operationalized | D19: 5 | E19: 5 | F19: 2 | G19: 2 | H19: 2 | I19: 5 | K19: Soil monitoring systems rarely track economic indicators, livelihood impacts, or poverty reduction contributions. | L19: Comprehensive soil frameworks connecting soil health improvements to measurable economic benefits across diverse contexts. | M19: Regional differences in soil-livelihood connections, economic monitoring capacity, and poverty-soil health relationships. | N19: Economic indicator development, livelihood impact tracking methodologies, and poverty-soil relationships analysis. | O19: Collaboration with Digital Accelerator for systems; Markets Program for economic frameworks.
C20: HLO 3.2: Network of long-term monitoring sites for carbon storage assessment | D20: 4 | E20: 2 | F20: 2 | G20: 2 | H20: 2 | I20: 2 | K20: Long-term research rarely quantifies economic returns, livelihood enhancement, or poverty reduction from soil investments. | L20: Monitoring networks documenting long-term economic benefits of soil health investments across diverse socioeconomic contexts. | M20: Variations in research economic capacity, livelihood impact metrics, and poverty reduction monitoring approaches. | N20: Economic return assessment methodologies, long-term livelihood tracking, and poverty impact monitoring protocols. | O20: Partnership with Foresight services for projections; Markets Program for economic analysis.
C21: HLO 3.3: Impacts of agricultural practices quantified and catalogued | D21: 4 | E21: 2 | F21: 2 | G21: 2 | H21: 2 | I21: 2 | K21: Limited evidence on economic returns, employment effects, or poverty reduction impacts of soil management practices. | L21: Comprehensive evidence base linking soil management practices to quantified economic benefits across diverse contexts. | M21: Regional differences in economic research coverage, livelihood impact methodologies, and poverty-soil evidence synthesis. | N21: Economic impact assessment tools, livelihood benefit quantification methods, and poverty reduction evidence frameworks. | O21: Integration with Markets Program for economic analysis; Scaling Program for business models.
C22: HLO 3.4: Evidence for policy makers on soil health translated to accessible formats | D22: 4 | E22: 2 | F22: 2 | G22: 2 | H22: 2 | I22: 2 | K22: Soil health policy communication rarely emphasizes economic returns, employment creation, or poverty reduction potential. | L22: Soil policies explicitly connecting soil health to economic prosperity and poverty reduction through accessible evidence. | M22: Differences in policy economic framing, livelihood emphasis in governance, and poverty reduction orientation in soil health. | N22: Economic policy analysis, poverty impact communication strategies, and livelihood-focused stakeholder engagement. | O22: Partnership with Policy Program; Communications for economic messaging.
C23: HLO 4.1: Capacity and networks of plant health practitioners improved | D23: 2 | E23: 2 | F23: 2 | G23: 2 | H23: 2 | I23: 4 | K23: Plant health systems rarely optimize for economic outcomes, livelihood protection, or poverty reduction potential. | L23: Practitioner networks balancing plant protection with explicit livelihood preservation and economic optimization objectives. | M23: Regional variations in pest economic impacts, plant health business models, and poverty-pest management relationships. | N23: Economic impact training, livelihood-centered plant health approaches, and poverty-sensitive management strategies. | O23: Collaboration with Capacity Sharing Accelerator; Markets Program for business models.
C24: HLO 4.2: Improved pest and disease monitoring and modeling tools | D24: 3 | E24: 3 | F24: 3 | G24: 3 | H24: 3 | I24: 3 | K24: Monitoring systems rarely prioritize economic threats, livelihood impacts, or poverty implications of pest outbreaks. | L24: Advanced surveillance systems enabling economically-optimized pest management decisions that protect critical livelihood sources. | M24: Differences in monitoring economic integration, livelihood-threat assessment, and poverty-sensitive prioritization approaches. | N24: Economic impact modeling, livelihood vulnerability assessment, and poverty-sensitive prioritization frameworks. | O24: Partnership with Digital Accelerator for systems; Markets Program for value chain analysis.
C25: HLO 4.3: Surveillance data and prevention strategies available | D25: 3 | E25: 2 | F25: 4 | G25: 4 | H25: 2 | I25: 3 | K25: Prevention strategies rarely differentiate economic importance of crops, livelihood significance, or poverty reduction potential. | L25: Evidence-based prevention approaches explicitly prioritizing economic high-leverage points in agricultural systems. | M25: Regional variations in pest economic impacts, prevention return-on-investment potential, and poverty-sensitive prioritization. | N25: Economic prioritization frameworks, livelihood impact assessment tools, and poverty-focused prevention strategies. | O25: Integration with Markets Program for value chain analysis; Policy Program for implementation frameworks.
C26: HLO 4.4: Eco-friendly options for integrated pest management developed | D26: 4 | E26: 4 | F26: 5 | G26: 5 | H26: 4 | I26: 5 | K26: Ecological approaches rarely optimize for economic returns, labor requirements, or poverty reduction potential. | L26: Integrated management systems balancing environmental sustainability with explicit economic optimization across farm types. | M26: Differences in ecological-economic integration, green market development, and poverty-sensitive IPM implementation. | N26: Economic return analysis for ecological approaches, livelihood impact assessment tools, and poverty reduction metrics. | O26: Collaboration with Biodiversity Program for approaches; Markets Program for economic analysis.
... C44: HLO 8.5: Policy-related information for sustainable farming systems | D44: 2 | E44: 2 | F44: 4 | G44: 1 | H44: 2 | I44: 2 | K44: Policy engagement often separates technical and economic evidence, limiting integrated approaches to agricultural development. | L44: Systematic integration of farming systems evidence into economically-optimized agricultural policy across governance scales. | M44: Regional variations in policy-market interfaces, economic-technical integration, and poverty-focused governance approaches. | N44: Economic-technical policy analysis, integrated evidence synthesis, and poverty-focused communication strategies. | O44: Strong integration with Policy Program; Markets Program for economic frameworks.

Sheet 3.Social_inclusion
C1: Social inclusion Indicator
A2: VH | B2: 5 | D2: LAC | E2: CWANA | F2: WCA | G2: ESA | H2: SA | I2: SEA
A3: H | B3: 4 | C3: Total score by column | D3: =SUM(D11:D61) -> 104 | E3: =SUM(E11:E61) -> 104 | F3: =SUM(F11:F61) -> 104 | G3: =SUM(G11:G61) -> 104 | H3: =SUM(H11:H61) -> 104 | I3: =SUM(I11:I61) -> 104
A4: MH | B4: 3 | C4: VH count by column | D4: =COUNTIF(D$11:D$61, 5) -> 5 | E4: =COUNTIF(E$11:E$61, 5) -> 3 | F4: =COUNTIF(F$11:F$61, 5) -> 3 | G4: =COUNTIF(G$11:G$61, 5) -> 4 | H4: =COUNTIF(H$11:H$61, 5) -> 7 | I4: =COUNTIF(I$11:I$61, 5) -> 8
A5: M | B5: 2 | C5: H count by column | D5: =COUNTIF(D$11:D$61, 4) -> 10 | E5: =COUNTIF(E$11:E$61, 4) -> 12 | F5: =COUNTIF(F$11:F$61, 4) -> 11 | G5: =COUNTIF(G$11:G$61, 4) -> 8 | H5: =COUNTIF(H$11:H$61, 4) -> 3 | I5: =COUNTIF(I$11:I$61, 4) -> 6
A6: L | B6: 1 | C6: MH count by column | D6: =COUNTIF(D$11:D$61, 3) -> 6 | E6: =COUNTIF(E$11:E$61, 3) -> 5 | F6: =COUNTIF(F$11:F$61, 3) -> 11 | G6: =COUNTIF(G$11:G$61, 3) -> 14 | H6: =COUNTIF(H$11:H$61, 3) -> 13 | I6: =COUNTIF(I$11:I$61, 3) -> 5
C7: M count by column | D7: =COUNTIF(D$11:D$61, 2) -> 8 | E7: =COUNTIF(E$11:E$61, 2) -> 12 | F7: =COUNTIF(F$11:F$61, 2) -> 3 | G7: =COUNTIF(G$11:G$61, 2) -> 2 | H7: =COUNTIF(H$11:H$61, 2) -> 7 | I7: =COUNTIF(I$11:I$61, 2) -> 10
